Workbook
Name Actual_Expenses: '[1]Budget Overview'!$G$8
Name Actual_Income: '[1]Budget Overview'!$D$11
Name ActualNumberOfPayments: IFERROR(IF(LoanIsGood,IF(PaymentsPerYear=1,1,MATCH(0.01,End_Bal,-1)+1)),"")
Name Annual_Dividend: OFFSET(#REF!,0,0,IF(#REF!>100,100,#REF!))
Name AO: '[2]Repayment Schedule'!$F$7
Name ARMF_120: OFFSET([3]ARMF!$J$1,[3]ARMF!$Z$1+1,0,[3]ARMF!$AB$1,1)
Name ARMF_120_2: OFFSET([3]ARMF!$J$1,[3]ARMF!$AF$1+1,0,[3]ARMF!$AH$1,1)
Name ARMF_20: OFFSET([3]ARMF!$H$1,[3]ARMF!$Z$1+1,0,[3]ARMF!$AB$1,1)
Name ARMF_20_2: OFFSET([3]ARMF!$H$1,[3]ARMF!$AF$1+1,0,[3]ARMF!$AH$1,1)
Name ARMF_50: OFFSET([3]ARMF!$I$1,[3]ARMF!$Z$1+1,0,[3]ARMF!$AB$1,1)
Name ARMF_50_2: OFFSET([3]ARMF!$I$1,[3]ARMF!$AF$1+1,0,[3]ARMF!$AH$1,1)
Name ARMF_D_2: OFFSET([3]ARMF!$A$1,[3]ARMF!$AF$1+1,0,[3]ARMF!$AH$1,1)
Name ARMF_DATE: OFFSET([3]ARMF!$A$1,[3]ARMF!$Z$1+1,0,[3]ARMF!$AB$1,1)
Name ARMF_P_2: OFFSET([3]ARMF!$B$1,[3]ARMF!$AF$1+1,0,[3]ARMF!$AH$1,1)
Name ARMF_PRICE: OFFSET([3]ARMF!$B$1,[3]ARMF!$Z$1+1,0,[3]ARMF!$AB$1,1)
Name Categories: [4]!TblDV4[Category]
Name ColumnTitle1: [2]!PaymentSchedule[[#Headers],[PMT NO]]
Name current_date: DATE(2023,11,11)
Name End_Bal: [2]!PaymentSchedule[ENDING BALANCE]
Name Expenses_header_row: ROW([4]!Expense[[#Headers],[Expense]])
Name Expenses_max_row: MAX(ROW([4]!Expense[#Data]))
Name Expenses_min_row: MIN(ROW([4]!Expense[#Data]))
Name Expenses_total_row: ROW('[4]Budget Planning'!$C$36)
Name ExtraPayments: '[2]Excel Amortization Schedule'!$E$14
Name income_header_row: ROW([4]!Income[[#Headers],[Income]])
Name income_max_row: MAX(ROW([4]!Income[#Data]))
Name Income_min_row: MIN(ROW([4]!Income[#Data]))
Name income_total_row: ROW('[4]Budget Planning'!$C$20)
Name InterestRate: '[2]Excel Amortization Schedule'!$E$9
Name is_empty: '[4]Budget Dashboard'!$H1
Name LastCol: MATCH(REPT("z",255),'[2]Excel Amortization Schedule'!$16:$16)
Name LastRow: MATCH(9.99E+307,'[2]Excel Amortization Schedule'!$B:$B)
Name List_Categories: [5]!Category_List_Table[To add a category, type below]
Name loan: '[2]Repayment Schedule'!$B$8
Name LoanAmount: '[2]Excel Amortization Schedule'!$E$8
Name LoanIsGood: ('[2]Excel Amortization Schedule'!$E$8*'[2]Excel Amortization Schedule'!$E$9*'[2]Excel Amortization Schedule'!$E$10*'[2]Excel Amortization Schedule'!$E$12)>0
Name LoanPeriod: '[2]Excel Amortization Schedule'!$E$10
Name LoanStartDate: '[2]Excel Amortization Schedule'!$E$12
Name Name1: '[6]Week 1'!$B$6
Name Name2: '[6]Week 1'!$B$13
Name Name3: '[6]Week 1'!$B$20
Name Name4: '[6]Week 1'!$B$27
Name New_Balance: OFFSET(#REF!,0,0,IF(#REF!>100,100,#REF!))
Name P_Annual_Dividend: OFFSET([7]Portfolio!$D$32,0,0,IF([7]Portfolio!$D$13>100,100,[7]Portfolio!$D$13))
Name P_New_Balance: OFFSET(#REF!,0,0,IF(#REF!>100,100,#REF!))
Name P_Principal: OFFSET([7]Portfolio!$C$32,0,0,IF([7]Portfolio!$D$13>100,100,[7]Portfolio!$D$13))
Name P_Year: OFFSET([7]Portfolio!$B$32,0,0,IF([7]Portfolio!$D$13>100,100,[7]Portfolio!$D$13))
Name P_Yield_On_Cost: OFFSET([7]Portfolio!$F$32,0,0,IF([7]Portfolio!$D$13>100,100,[7]Portfolio!$D$13))
Name PAFA_120: OFFSET([3]PAFA!$J$1,[3]PAFA!$Z$1+1,0,[3]PAFA!$AB$1,1)
Name PAFA_120_2: OFFSET([3]PAFA!$J$1,[3]PAFA!$AF$1+1,0,[3]PAFA!$AH$1,1)
Name PAFA_20: OFFSET([3]PAFA!$H$1,[3]PAFA!$Z$1+1,0,[3]PAFA!$AB$1,1)
Name PAFA_20_2: OFFSET([3]PAFA!$H$1,[3]PAFA!$AF$1+1,0,[3]PAFA!$AH$1,1)
Name PAFA_50: OFFSET([3]PAFA!$I$1,[3]PAFA!$Z$1+1,0,[3]PAFA!$AB$1,1)
Name PAFA_50_2: OFFSET([3]PAFA!$I$1,[3]PAFA!$AF$1+1,0,[3]PAFA!$AH$1,1)
Name PAFA_D_2: OFFSET([3]PAFA!$A$1,[3]PAFA!$AF$1+1,0,[3]PAFA!$AH$1,1)
Name PAFA_DATE: OFFSET([3]PAFA!$A$1,[3]PAFA!$Z$1+1,0,[3]PAFA!$AB$1,1)
Name PAFA_P_2: OFFSET([3]PAFA!$B$1,[3]PAFA!$AF$1+1,0,[3]PAFA!$AH$1,1)
Name PAFA_PRICE: OFFSET([3]PAFA!$B$1,[3]PAFA!$Z$1+1,0,[3]PAFA!$AB$1,1)
Name PAMA_120: OFFSET([3]PAMA!$J$1,[3]PAMA!$Z$1+1,0,[3]PAMA!$AB$1,1)
Name PAMA_120_2: OFFSET([3]PAMA!$J$1,[3]PAMA!$AF$1+1,0,[3]PAMA!$AH$1,1)

Sheet Retirement Dashboard
B1: It's time to plan for your retirement. | H1: Singaporean CPF Allocation Rates (From 2025 Jan 1) Salary above $750/Month | Q1: Retirement Sum (Est FRS Increase 3% to 3.5% pa) | V1: Estimated Pay Out (Est increase 3% to 3.5%pa)
B2: Before we begin, let’s understand how ready you are for retirement. | H2: Age Band | I2: Total CPF | J2: OA | K2: SA | L2: MA | M2: Total | N2: Employer | O2: Employee | Q2: Age | R2: Year | S2: BRS | T2: FRS | U2: ERS | V2: BRS | W2: FRS | X2: ERS
B3: 2025 | H3: 35 & Below | I3: =SUM(J3:L3) -> 0.37 | J3: =62.17%*M3 -> 0.230029 | K3: =16.21%*M3 -> 0.059977 | L3: =21.62%*M3 -> 0.079994 | M3: =N3+O3 -> 0.37 | N3: 0.17 | O3: 0.2 | Q3: =C9 -> 27 | R3: =B3 -> 2025 | S3: 106500 | T3: 213000 | U3: 426000 | V3: 840 | W3: 1590 | X3: 3330
H4: Above 35-45 | I4: =SUM(J4:L4) -> 0.37 | J4: =56.77%*M4 -> 0.210049 | K4: =18.91%*M4 -> 0.069967 | L4: =24.32%*M4 -> 0.089984 | M4: =N4+O4 -> 0.37 | N4: 0.17 | O4: 0.2 | Q4: =Q3+1 -> 28 | R4: =R3+1 -> 2026 | S4: 110200 | T4: 220440 | U4: 440800 | V4: 850 | W4: 1600 | X4: =X3*103.31% -> 3440.223
B5: VIP Information | H5: Above 45-50 | I5: =SUM(J5:L5) -> 0.37 | J5: =51.36%*M5 -> 0.190032 | K5: =21.62%*M5 -> 0.079994 | L5: =27.02%*M5 -> 0.099974 | M5: =N5+O5 -> 0.37 | N5: 0.17 | O5: 0.2 | Q5: =Q4+1 -> 29 | R5: =R4+1 -> 2027 | S5: 114100 | T5: 228200 | U5: 456400 | V5: 900 | W5: 1670 | X5: 3550
B6: Your Name | C6: Siti | D6: Desired Retirement Age | E6: 65 | H6: Above 50-55 | I6: =SUM(J6:L6) -> 0.37 | J6: =40.55%*M6 -> 0.150035 | K6: =31.08%*M6 -> 0.114996 | L6: =28.37%*M6 -> 0.104969 | M6: =N6+O6 -> 0.37 | N6: 0.17 | O6: 0.2 | Q6: =Q5+1 -> 30 | R6: =R5+1 -> 2028 | S6: =(S5*103.47%) -> 118059.27 | T6: =T5*103.5% -> 236187 | U6: =U5*103.5% -> 472374 | V6: 930 | W6: 1730 | X6: =X5*103.31% -> 3667.505
B7: Gender | C7: Female | D7: Choice of CPFL | E7: FRS | H7: Above 55-60 | I7: =SUM(J7:L7) -> 0.299494 | J7: =30.872%*M7 -> 0.100334 | K7: =27.41%*M7 -> 0.0890825 | L7: =33.87%*M7 -> 0.1100775 | M7: =N7+O7 -> 0.325 | N7: =32.5%-17% -> 0.155 | O7: 0.17 | Q7: =Q6+1 -> 31 | R7: =R6+1 -> 2029 | S7: =(S6*103.5%) -> 122191.34 | T7: =T6*103.5% -> 244453.54 | U7: =U6*103.5% -> 488907.09 | V7: 950 | W7: 1780 | X7: =X6*103.31% -> 3788.8994
B8: Your Birthday | C8: 36331 | H8: Above 60-65 | I8: =SUM(J8:L8) -> 0.234295 | J8: =15.62%*M8 -> 0.036707 | K8: =36.36%*M8 -> 0.085446 | L8: =47.72%*M8 -> 0.112142 | M8: =N8+O8 -> 0.235 | N8: =23.5%-O8 -> 0.12 | O8: 0.115 | Q8: =Q7+1 -> 32 | R8: =R7+1 -> 2030 | S8: =(S7*103.5%) -> 126468.04 | T8: =T7*103.5% -> 253009.42 | U8: =U7*103.5% -> 506018.84 | V8: 980 | W8: 1840 | X8: =X7*103.31% -> 3914.312
B9: Your Age Current | C9: =ROUND((TODAY()-C8)/365,0) -> 27 | H9: Above 65 -70 | I9: =SUM(J9:L9) -> 0.165 | J9: =6.07%*M9 -> 0.0100155 | K9: =30.3%*M9 -> 0.049995 | L9: =63.63%*M9 -> 0.1049895 | M9: =N9+O9 -> 0.165 | N9: =16.5%-O9 -> 0.09 | O9: 0.075 | Q9: =Q8+1 -> 33 | R9: =R8+1 -> 2031 | S9: =(S8*103.5%) -> 130894.42 | T9: =T8*103.5% -> 261864.75 | U9: =U8*103.5% -> 523729.5 | V9: =V8+30 -> 1010 | W9: =W8+60 -> 1900 | X9: =X8*103.31% -> 4043.8757
B10: Current Gross Wage Per month | C10: 4000 | H10: Above 70 | I10: =SUM(J10:L10) -> 0.125 | J10: =8%*M10 -> 0.01 | K10: =8%*M10 -> 0.01 | L10: =84%*M10 -> 0.105 | M10: =N10+O10 -> 0.125 | N10: =12.5%-O10 -> 0.075 | O10: 0.05 | Q10: =Q9+1 -> 34 | R10: =R9+1 -> 2032 | S10: =(S9*103.5%) -> 135475.73 | T10: =T9*103.5% -> 271030.01 | U10: =U9*103.5% -> 542060.03 | V10: =V9+30 -> 1040 | W10: =W9+60 -> 1960 | X10: =X9*103.31% -> 4177.728
B11: TTL mths of salary +AWS+Bonus | C11: 14 | Q11: =Q10+1 -> 35 | R11: =R10+1 -> 2033 | S11: =(S10*103.5%) -> 140217.38 | T11: =T10*103.5% -> 280516.07 | U11: =U10*103.5% -> 561032.13 | V11: =V10+30 -> 1070 | W11: =W10+60 -> 2020 | X11: =X10*103.31% -> 4316.0108
B12: Current Gross Wage per Year | C12: =C10*C11 -> 56000 | Q12: =Q11+1 -> 36 | R12: =R11+1 -> 2034 | S12: =(S11*103.5%) -> 145124.99 | T12: =T11*103.5% -> 290334.13 | U12: =U11*103.5% -> 580668.26 | V12: =V11+30 -> 1100 | W12: =W11+60 -> 2080 | X12: =X11*103.31% -> 4458.8708
B13: Current Additional Month OA | C13: =C10*E13 -> 920.116 | D13: OA Band | E13: =IF($C$9<=35,J3,IF($C$9<=45,J4,IF($C$9<=50,J5,IF($C$9<=55,J6,IF($C$9<=60,J7,IF($C$9<=65,J8,IF(J14<=70,J9,J10))))))) -> 0.230029 | Q13: =Q12+1 -> 37 | R13: =R12+1 -> 2035 | S13: =(S12*103.5%) -> 150204.36 | T13: =T12*103.5% -> 300495.82 | U13: =U12*103.5% -> 600991.64 | V13: =V12+30 -> 1130 | W13: =W12+60 -> 2140 | X13: =X12*103.31% -> 4606.4594
B14: Current Additional Month SA | C14: =C10*E14 -> 239.908 | D14: SA Band | E14: =IF($C$9<=35,K3,IF($C$9<=45,K4,IF($C$9<=50,K5,IF($C$9<=55,K6,IF($C$9<=60,K7,IF($C$9<=65,K8,IF($C$9<=70,K9,K10))))))) -> 0.059977 | Q14: =Q13+1 -> 38 | R14: =R13+1 -> 2036 | S14: =(S13*103.5%) -> 155461.51 | T14: =T13*103.5% -> 311013.18 | U14: =U13*103.5% -> 622026.35 | V14: =V13+30 -> 1160 | W14: =W13+60 -> 2200 | X14: =X13*103.31% -> 4758.9332
B15: Current Additional Month MA | C15: =E15*C10 -> 319.976 | D15: MA Band | E15: =IF($C$9<=35,L3,IF($C$9<=45,L4,IF($C$9<=50,L5,IF($C$9<=55,L6,IF($C$9<=60,L7,IF($C$9<=65,L8,IF($C$9<=70,L9,L10))))))) -> 0.079994 | Q15: =Q14+1 -> 39 | R15: =R14+1 -> 2037 | S15: =(S14*103.5%) -> 160902.67 | T15: =T14*103.5% -> 321898.64 | U15: =U14*103.5% -> 643797.27 | V15: =V14+30 -> 1190 | W15: =W14+60 -> 2260 | X15: =X14*103.31% -> 4916.4539
B16: Employer CPF Contribution | C16: =E16*C10 -> 680 | D16: Employer Contribution | E16: =IF($C$9<=35,N3,IF($C$9<=45,N4,IF($C$9<=50,N5,IF($C$9<=55,N6,IF($C$9<=60,N7,IF($C$9<=65,N8,IF($C$9<=70,N9,N10))))))) -> 0.17 | Q16: =Q15+1 -> 40 | R16: =R15+1 -> 2038 | S16: =(S15*103.5%) -> 166534.26 | T16: =T15*103.5% -> 333165.09 | U16: =U15*103.5% -> 666330.18 | V16: =V15+30 -> 1220 | W16: =W15+60 -> 2320 | X16: =X15*103.31% -> 5079.1885
B17: Employee CPF Contribution | C17: =E17*C10 -> 800 | D17: Employee Contribution | E17: =IF($C$9<=35,O3,IF($C$9<=45,O4,IF($C$9<=50,O5,IF($C$9<=55,O6,IF($C$9<=60,O7,IF($C$9<=65,O8,IF($C$9<=70,O9,O10))))))) -> 0.2 | Q17: =Q16+1 -> 41 | R17: =R16+1 -> 2039 | S17: =(S16*103.5%) -> 172362.96 | T17: =T16*103.5% -> 344825.87 | U17: =U16*103.5% -> 689651.74 | V17: =V16+30 -> 1250 | W17: =W16+60 -> 2380 | X17: =X16*103.31% -> 5247.3096
B18: Total CPF Contribution | C18: =C17+C16 -> 1480 | Q18: =Q17+1 -> 42 | R18: =R17+1 -> 2040 | S18: =(S17*103.5%) -> 178395.66 | T18: =T17*103.5% -> 356894.77 | U18: =U17*103.5% -> 713789.55 | V18: =V17+30 -> 1280 | W18: =W17+60 -> 2440 | X18: =X17*103.31% -> 5420.9956
B19: OA Balance YTD | C19: 21000 | D19: Estimated OA | E19: =C13*12*17 -> 187703.66 | Q19: =Q18+1 -> 43 | R19: =R18+1 -> 2041 | S19: =(S18*103.5%) -> 184639.51 | T19: =T18*103.5% -> 369386.09 | U19: =U18*103.5% -> 738772.18 | V19: =V18+30 -> 1310 | W19: =W18+60 -> 2500 | X19: =X18*103.31% -> 5600.4305
B20: SA Balance YTD | C20: 60000 | D20: Estimated SA | E20: =C14*12*17 -> 48941.232 | Q20: =Q19+1 -> 44 | R20: =R19+1 -> 2042 | S20: =(S19*103.5%) -> 191101.89 | T20: =T19*103.5% -> 382314.6 | U20: =U19*103.5% -> 764629.21 | V20: =V19+30 -> 1340 | W20: =W19+60 -> 2560 | X20: =X19*103.31% -> 5785.8048
B21: MA Balance YTD | C21: 40000 | D21: Estimated MA | E21: =C15*12*17 -> 65275.104 | Q21: =Q20+1 -> 45 | R21: =R20+1 -> 2043 | S21: =(S20*103.5%) -> 197790.46 | T21: =T20*103.5% -> 395695.61 | U21: =U20*103.5% -> 791391.23 | V21: =V20+30 -> 1370 | W21: =W20+60 -> 2620 | X21: =X20*103.31% -> 5977.3149
Q22: =Q21+1 -> 46 | R22: =R21+1 -> 2044 | S22: =(S21*103.5%) -> 204713.13 | T22: =T21*103.5% -> 409544.96 | U22: =U21*103.5% -> 819089.92 | V22: =V21+30 -> 1400 | W22: =W21+60 -> 2680 | X22: =X21*103.31% -> 6175.164
B23: CPFL | Q23: =Q22+1 -> 47 | R23: =R22+1 -> 2045 | S23: =(S22*103.5%) -> 211878.09 | T23: =T22*103.5% -> 423879.03 | U23: =U22*103.5% -> 847758.07 | V23: =V22+30 -> 1430 | W23: =W22+60 -> 2740 | X23: =X22*103.31% -> 6379.562
B24: Year Age 55 | C24: =YEAR(TODAY()) + (55 - (YEAR(TODAY()) - YEAR(C8))) -> 2054 | D24: Years to Age 55 | E24: =$C$24-YEAR(TODAY()) -> 28 | Q24: =Q23+1 -> 48 | R24: =R23+1 -> 2046 | S24: =(S23*103.5%) -> 219293.82 | T24: =T23*103.5% -> 438714.8 | U24: =U23*103.5% -> 877429.6 | V24: =V23+30 -> 1460 | W24: =W23+60 -> 2800 | X24: =X23*103.31% -> 6590.7255
B25: Estimated BRS | C25: =INDEX($S$2:$S$39,MATCH($C$24,$R$2:$R$39,1)) -> 288768.08 | D25: Estimated Payout | E25: =INDEX($V$2:$V$39,MATCH($C$24,$R$2:$R$39,1)) -> 1700 | Q25: =Q24+1 -> 49 | R25: =R24+1 -> 2047 | S25: =(S24*103.5%) -> 226969.1 | T25: =T24*103.5% -> 454069.82 | U25: =U24*103.5% -> 908139.64 | V25: =V24+30 -> 1490 | W25: =W24+60 -> 2860 | X25: =X24*103.31% -> 6808.8785
B26: Estimated FRS | C26: =INDEX($T$2:$T$39,MATCH($C$24,$R$2:$R$39,1)) -> 577703.61 | D26: Estimated Payout | E26: =INDEX($W$2:$W$39,MATCH($C$24,$R$2:$R$39,1)) -> 3280 | Q26: =Q25+1 -> 50 | R26: =R25+1 -> 2048 | S26: =(S25*103.5%) -> 234913.02 | T26: =T25*103.5% -> 469962.26 | U26: =U25*103.5% -> 939924.52 | V26: =V25+30 -> 1520 | W26: =W25+60 -> 2920 | X26: =X25*103.31% -> 7034.2524
B27: Estimated ERS | C27: =INDEX($U$2:$U$39,MATCH($C$24,$R$2:$R$39,1)) -> 1155407.2 | D27: Estimated Payout | E27: =INDEX($X$2:$X$39,MATCH($C$24,$R$2:$R$39,1)) -> 8552.0871 | Q27: =Q26+1 -> 51 | R27: =R26+1 -> 2049 | S27: =(S26*103.5%) -> 243134.98 | T27: =T26*103.5% -> 486410.94 | U27: =U26*103.5% -> 972821.88 | V27: =V26+30 -> 1550 | W27: =W26+60 -> 2980 | X27: =X26*103.31% -> 7267.0861
Q28: =Q27+1 -> 52 | R28: =R27+1 -> 2050 | S28: =(S27*103.5%) -> 251644.7 | T28: =T27*103.5% -> 503435.32 | U28: =U27*103.5% -> 1006870.6 | V28: =V27+30 -> 1580 | W28: =W27+60 -> 3040 | X28: =X27*103.31% -> 7507.6267
B29: Inflation Adjusted | C29: 0.02 | D29: Inflation Adjusted BRS | E29: =FV(-$C$29,$C$24-YEAR(TODAY()),0,-E25) -> 965.5595 | Q29: =Q28+1 -> 53 | R29: =R28+1 -> 2051 | S29: =(S28*103.5%) -> 260452.27 | T29: =T28*103.5% -> 521055.56 | U29: =U28*103.5% -> 1042111.1 | V29: =V28+30 -> 1610 | W29: =W28+60 -> 3100 | X29: =X28*103.31% -> 7756.1291
D30: Inflation Adjusted FRS | E30: =FV(-$C$29,$C$24-YEAR(TODAY()),0,-E26) -> 1862.9619 | Q30: =Q29+1 -> 54 | R30: =R29+1 -> 2052 | S30: =(S29*103.5%) -> 269568.09 | T30: =T29*103.5% -> 539292.51 | U30: =U29*103.5% -> 1078585 | V30: =V29+30 -> 1640 | W30: =W29+60 -> 3160 | X30: =X29*103.31% -> 8012.857
D31: Inflation Adjusted ERS | E31: =FV(-$C$29,$C$24-YEAR(TODAY()),0,-E27) -> 4857.3817 | Q31: =Q30+1 -> 55 | R31: =R30+1 -> 2053 | S31: =(S30*103.5%) -> 279002.98 | T31: =T30*103.5% -> 558167.74 | U31: =U30*103.5% -> 1116335.5 | V31: =V30+30 -> 1670 | W31: =W30+60 -> 3220 | X31: =X30*103.31% -> 8278.0826
Q32: =Q31+1 -> 56 | R32: =R31+1 -> 2054 | S32: =(S31*103.5%) -> 288768.08 | T32: =T31*103.5% -> 577703.61 | U32: =U31*103.5% -> 1155407.2 | V32: =V31+30 -> 1700 | W32: =W31+60 -> 3280 | X32: =X31*103.31% -> 8552.0871
B33: Accumulation CPFL At Age 65 | Q33: =Q32+1 -> 57 | R33: =R32+1 -> 2055 | S33: =(S32*103.5%) -> 298874.96 | T33: =T32*103.5% -> 597923.24 | U33: =U32*103.5% -> 1195846.5 | V33: =V32+30 -> 1730 | W33: =W32+60 -> 3340 | X33: =X32*103.31% -> 8835.1612
B34: Estimated Accumulation CPFL BRS | C34: =C25*(1+0.04)^10 -> 427447.3 | D34: Estimated Accumulation FRS | E34: =C26*(1+0.04)^10 -> 855142.47 | Q34: =Q33+1 -> 58 | R34: =R33+1 -> 2056 | S34: =(S33*103.5%) -> 309335.59 | T34: =T33*103.5% -> 618850.55 | U34: =U33*103.5% -> 1237701.1 | V34: =V33+30 -> 1760 | W34: =W33+60 -> 3400 | X34: =X33*103.31% -> 9127.605
B35: Monthly Payout till Age 80 | C35: =E25*12*15 -> 306000 | D35: Monthly Payout till Age 80 | E35: =E26*12*15 -> 590400 | Q35: =Q34+1 -> 59 | R35: =R34+1 -> 2057 | S35: =(S34*103.5%) -> 320162.33 | T35: =T34*103.5% -> 640510.32 | U35: =U34*103.5% -> 1281020.6 | V35: =V34+30 -> 1790 | W35: =W34+60 -> 3460 | X35: =X34*103.31% -> 9429.7287
B36: CPBL Death Payout | C36: =C34-C35 -> 121447.3 | D36: CPBL Death Payout | E36: =E34-E35 -> 264742.47 | Q36: =Q35+1 -> 60 | R36: =R35+1 -> 2058 | S36: =(S35*103.5%) -> 331368.02 | T36: =T35*103.5% -> 662928.18 | U36: =U35*103.5% -> 1325856.4 | V36: =V35+30 -> 1820 | W36: =W35+60 -> 3520 | X36: =X35*103.31% -> 9741.8528
Q37: =Q36+1 -> 61 | R37: =R36+1 -> 2059 | S37: =(S36*103.5%) -> 342965.9 | T37: =T36*103.5% -> 686130.67 | U37: =U36*103.5% -> 1372261.3 | V37: =V36+30 -> 1850 | W37: =W36+60 -> 3580 | X37: =X36*103.31% -> 10064.308
Q38: =Q37+1 -> 62 | R38: =R37+1 -> 2060 | S38: =(S37*103.5%) -> 354969.7 | T38: =T37*103.5% -> 710145.24 | U38: =U37*103.5% -> 1420290.5 | V38: =V37+30 -> 1880 | W38: =W37+60 -> 3640 | X38: =X37*103.31% -> 10397.437
B39: Medical Insurance | Q39: =Q38+1 -> 63 | R39: =R38+1 -> 2061 | S39: =(S38+3900) -> 358869.7 | T39: =T38*103.5% -> 735000.33 | U39: =U38*103.5% -> 1470000.7 | V39: =V38+30 -> 1910 | W39: =W38+60 -> 3700 | X39: =X38*103.31% -> 10741.592
B40: Private Hospital Plan | C40: Yes
...

Sheet CPF TB
A1: F
B2: CPFL | AK2: CPF Interest Earned | AL2: Before Age 55 | AM2: CPF Interest Earned | AN2: After Age 55 | AR2: Retirement Sum (Est FRS Increase 3% to 3.5% pa) | AW2: Estimated Pay Out (Est increase 3% to 3.5%pa) | BA2: Careshield Life Premium estimation | BF2: Singaporean CPF Allocation Rates (From 2025 Jan 1) Salary above $750/Month
B3: MA Projection | M3: SA/RA Projection | T3: OA Projection | AB3: RAProjection | AK3: 1st 20K OA | AL3: 0.035 | AM3: 1st 20K OA | AN3: 0.06 | AR3: Age | AS3: Year | AT3: BRS | AU3: FRS | AV3: ERS | AW3: BRS | AX3: FRS | AY3: ERS | BA3: Premium Est Increase | BB3: 0.02 | BC3: Payout Est Increase | BD3: 0.02 | BF3: Age Band | BG3: Total CPF | BH3: OA | BI3: SA | BJ3: MA | BK3: Total | BL3: Employer | BM3: Employee
B4: Age | C4: CareShield Premium | D4: Medishield Premium | E4: Private Shield AWL | F4: Care Secure Premium | G4: Additional MA by Salary | H4: YOY MA - Outflow | I4: MA earned Interest YoY | J4: Excess Transfer to SA | K4: Total MA After Cap | M4: Transfer from MA | N4: Additional SA from Salary | O4: SA Before Int Earned | P4: 1st 40K Interest Earned YoY | Q4: Remaining Int Earned YoY | R4: Total SA | T4: Additional OA from Salary | U4: Housing Loan | V4: DPS | W4: OA before Int Earned | X4: 1st 20K Interest Earned YoY | Y4: Remaining Int Earned YoY | Z4: Total OA | AB4: BRS | AC4: FRS | AD4: ERS | AK4: Remaining OA | AL4: 0.025 | AM4: Next 20K OA | AN4: 0.05 | BA4: Age | BB4: Female | BC4: Male | BD4: Payout | BF4: 35 & Below | BG4: =SUM(BH4:BJ4) -> 0.37 | BH4: =62.17%*BK4 -> 0.230029 | BI4: =16.21%*BK4 -> 0.059977 | BJ4: =21.62%*BK4 -> 0.079994 | BK4: =BL4+BM4 -> 0.37 | BL4: 0.17 | BM4: 0.2
B5: =BH30 -> 52 | C5: =INDEX(BB5:BC42, MATCH(B5, BA5:BA42, 0), MATCH('Retirement Dashboard'!$C$7, BB4:BC4, 0)) -> 391.13286 | D5: =IF(B5<=20,$AL$14,IF(B5<=30,$AL$15,IF(B5<=40,$AL$16,IF(B5<=50,$AL$17,IF(B5<=60,$AL$18,IF(B5<=65,$AL$19,IF(B5<=70,$AL$20, IF(B5<=73,$AL$21,IF(B5<=75,$AL$22,IF(B5<=78,$AL$23,IF(B5<=80,$AL$24,IF(B5<=83,$AL$25,IF(B5<=85,$AL$26,IF(B5<=90,$AL$27,$AL$28)))))))))))))) -> 800 | E5: =IF(B5<=20,$AM$14,IF(B5<=30,$AM$15,IF(B5<=40,$AM$16,IF(B5<=50,$AM$17,IF(B5<=60,$AM$18,IF(B5<=65,$AM$19,IF(B5<=70,$AM$20, IF(B5<=73,$AM$21,IF(B5<=75,$AM$22,IF(B5<=78,$AM$23,IF(B5<=80,$AM$24,IF(B5<=83,$AM$25,IF(B5<=85,$AM$26,IF(B5<=90,$AM$27,$AM$28)))))))))))))) -> 600 | F5: =IF(AND('Retirement Dashboard'!$C$42="Yes", B5<= 'Retirement Dashboard'!$E$42), 600, 0) -> 600 | G5: =IF(B5<'Retirement Dashboard'!$E$6,IF(B5<=35,$BJ$4,IF(B5<=45,$BJ$5,IF(B5<=50,$BJ$6,IF(B5<=55,$BJ$7,IF(B5<=60,$BJ$8,IF(B5<=65,$BJ$9,IF(B5<=70,$BJ$10,$BJ$11)))))))*'Retirement Dashboard'!$C$12,0) -> 5878.264 | H5: ='Retirement Dashboard'!C21-C5-D5-E5-F5+G5 -> 43487.131 | I5: =$AL$8*H5 -> 1739.4852 | J5: =IF(I5+H5-$AL$35>0,I5+H5-$AL$35,0) -> 0 | K5: =H5+I5-J5 -> 45226.616 | M5: =IF(J5>=0,J5,0) -> 0 | N5: =IF(B5<$BH$31,IF(B6<=35,$BI$4,IF(B6<=45,$BI$5,IF(B6<=50,$BI$6,IF(B6<=55,$BI$7,IF(B6<=60,$BI$8,IF(B6<=65,$BI$9,IF(B6<=70,$BI$10,$BI$11)))))))*'Retirement Dashboard'!$C$12,0) -> 6439.776 | O5: =M5+N5+'Retirement Dashboard'!C20 -> 66439.776 | P5: =IF(B5<=55,$AL$5,$AL$6)*(IF(O5>=40000,40000,O5)) -> 2000 | Q5: =$AN$7*IF(O5>=40000,O5-40000,0) -> 1321.9888 | R5: =IF(B5>=55,0,O5+P5+Q5) -> 69761.765 | T5: =IF(B5<$BH$31,IF(B5<=35,$BH$4,IF(B6<=45,$BH$5,IF(B6<=50,$BH$6,IF(B6<=55,$BH$7,IF(B6<=60,$BH$8,IF(B6<=65,$BH$9,IF(B6<=70,$BH$10,$BH$11)))))))*'Retirement Dashboard'!$C$12,0) -> 8401.96 | U5: =IF(B5<($BH$57+$BH$30),$BH$56*12,0) -> 0 | V5: =IF(B5<=34,$AN$31,IF(B5<=39,$AN$32,IF(B5<=44,$AN$33,IF(B5<=49,$AN$34,IF(B5<=54,$AN$35,IF(B5<=59,$AN$36,IF(B5<=69,$AN$37,0))))))) -> 188 | W5: =IF(B5>=55,T5-U5-V5+'Retirement Dashboard'!C19,T5-U5-V5+'Retirement Dashboard'!C19) -> 29213.96 | X5: =IF(B5<=55,$AL$3,$AN$3)*(IF(W5>=20000,20000,W5)) -> 700 | Y5: =$AL$4*IF(W5>=20000,W5-20000,W5) -> 230.349 | Z5: =W5+X5+Y5 -> 30144.309 | AK5: 1st 40K SA | AL5: 0.05 | AM5: Remaining OA | AN5: 0.025 | AR5: ='Retirement Dashboard'!C9 -> 27 | AS5: =BH27 -> 2025 | AT5: 106500 | AU5: 213000 | AV5: 426000 | AW5: 840 | AX5: 1590 | AY5: 3330 | BA5: 30 | BB5: 253 | BC5: 206 | BD5: 662 | BF5: Above 35-45 | BG5: =SUM(BH5:BJ5) -> 0.37 | BH5: =56.77%*BK5 -> 0.210049 | BI5: =18.91%*BK5 -> 0.069967 | BJ5: =24.32%*BK5 -> 0.089984 | BK5: =BL5+BM5 -> 0.37 | BL5: 0.17 | BM5: 0.2
B6: =B5+1 -> 53 | C6: =IF(B6>=67,$BI$55,C5+(1.0244%*C5)) -> 395.13962 | D6: =IF(B6<=20,$AL$14,IF(B6<=30,$AL$15,IF(B6<=40,$AL$16,IF(B6<=50,$AL$17,IF(B6<=60,$AL$18,IF(B6<=65,$AL$19,IF(B6<=70,$AL$20, IF(B6<=73,$AL$21,IF(B6<=75,$AL$22,IF(B6<=78,$AL$23,IF(B6<=80,$AL$24,IF(B6<=83,$AL$25,IF(B6<=85,$AL$26,IF(B6<=90,$AL$27,$AL$28)))))))))))))) -> 800 | E6: =IF(B6<=20,$AM$14,IF(B6<=30,$AM$15,IF(B6<=40,$AM$16,IF(B6<=50,$AM$17,IF(B6<=60,$AM$18,IF(B6<=65,$AM$19,IF(B6<=70,$AM$20, IF(B6<=73,$AM$21,IF(B6<=75,$AM$22,IF(B6<=78,$AM$23,IF(B6<=80,$AM$24,IF(B6<=83,$AM$25,IF(B6<=85,$AM$26,IF(B6<=90,$AM$27,$AM$28)))))))))))))) -> 600 | F6: =IF(AND('Retirement Dashboard'!$C$42="Yes", B6<= 'Retirement Dashboard'!$E$42), 600, 0) -> 600 | G6: =IF(B6<'Retirement Dashboard'!$E$6,IF(B6<=35,$BJ$4,IF(B6<=45,$BJ$5,IF(B6<=50,$BJ$6,IF(B6<=55,$BJ$7,IF(B6<=60,$BJ$8,IF(B6<=65,$BJ$9,IF(B6<=70,$BJ$10,$BJ$11)))))))*'Retirement Dashboard'!$C$12,0) -> 5878.264 | H6: =K5-C6-D6-E6-F6+G6 -> 48709.741 | I6: =$AL$8*H6 -> 1948.3896 | J6: =IF(I6+H6-$AL$35>0,I6+H6-$AL$35,0) -> 0 | K6: =H6+I6-J6 -> 50658.13 | M6: =IF(J6>=0,J6,0) -> 0 | N6: =IF(B6<$BH$31,IF(B7<=35,$BI$4,IF(B7<=45,$BI$5,IF(B7<=50,$BI$6,IF(B7<=55,$BI$7,IF(B7<=60,$BI$8,IF(B7<=65,$BI$9,IF(B7<=70,$BI$10,$BI$11)))))))*'Retirement Dashboard'!$C$12,0) -> 6439.776 | O6: =R5+N6+M6 -> 76201.541 | P6: =IF(B6<=55,$AL$5,$AN$6)*(IF(O6>=40000,40000,O6)) -> 2000 | Q6: =$AN$7*IF(O6>=40000,O6-40000,0) -> 1810.077 | R6: =O6+P6+Q6 -> 80011.618 | T6: =IF(B6<$BH$31,IF(B6<=35,$BH$4,IF(B7<=45,$BH$5,IF(B7<=50,$BH$6,IF(B7<=55,$BH$7,IF(B7<=60,$BH$8,IF(B7<=65,$BH$9,IF(B7<=70,$BH$10,$BH$11)))))))*'Retirement Dashboard'!$C$12,0) -> 8401.96 | U6: =IF(B6<($BH$57+$BH$30),$BH$56*12,0) -> 0 | V6: =IF(B6<=34,$AN$31,IF(B6<=39,$AN$32,IF(B6<=44,$AN$33,IF(B6<=49,$AN$34,IF(B6<=54,$AN$35,IF(B6<=59,$AN$36,IF(B6<=69,$AN$37,0))))))) -> 188 | W6: =Z5+T6-U6-V6 -> 38358.269 | X6: =IF(B6<=55,$AL$3,$AN$3)*(IF(W6>=20000,20000,W6)) -> 700 | Y6: =$AL$4*IF(W6>=20000,W6-20000,W6) -> 458.95673 | Z6: =W6+X6+Y6 -> 39517.226 | AK6: Remaining SA | AL6: 0.04 | AM6: 1st 10K RA | AN6: 0.06 | AR6: =AR5+1 -> 28 | AS6: =AS5+1 -> 2026 | AT6: 110200 | AU6: 220440 | AV6: 440800 | AW6: 850 | AX6: 1600 | AY6: =AY5*103.31% -> 3440.223 | BA6: 31 | BB6: =(100%+$BB$3)*BB5 -> 258.06 | BC6: =(100%+$BB$3)*BC5 -> 210.12 | BD6: =(100%+$BD$3)*BD5 -> 675.24 | BF6: Above 45-50 | BG6: =SUM(BH6:BJ6) -> 0.37 | BH6: =51.36%*BK6 -> 0.190032 | BI6: =21.62%*BK6 -> 0.079994 | BJ6: =27.02%*BK6 -> 0.099974 | BK6: =BL6+BM6 -> 0.37 | BL6: 0.17 | BM6: 0.2
B7: =B6+1 -> 54 | C7: =IF(B7>=67,$BI$55,C6+(1.0244%*C6)) -> 399.18743 | D7: =IF(B7<=20,$AL$14,IF(B7<=30,$AL$15,IF(B7<=40,$AL$16,IF(B7<=50,$AL$17,IF(B7<=60,$AL$18,IF(B7<=65,$AL$19,IF(B7<=70,$AL$20, IF(B7<=73,$AL$21,IF(B7<=75,$AL$22,IF(B7<=78,$AL$23,IF(B7<=80,$AL$24,IF(B7<=83,$AL$25,IF(B7<=85,$AL$26,IF(B7<=90,$AL$27,$AL$28)))))))))))))) -> 800 | E7: =IF(B7<=20,$AM$14,IF(B7<=30,$AM$15,IF(B7<=40,$AM$16,IF(B7<=50,$AM$17,IF(B7<=60,$AM$18,IF(B7<=65,$AM$19,IF(B7<=70,$AM$20, IF(B7<=73,$AM$21,IF(B7<=75,$AM$22,IF(B7<=78,$AM$23,IF(B7<=80,$AM$24,IF(B7<=83,$AM$25,IF(B7<=85,$AM$26,IF(B7<=90,$AM$27,$AM$28)))))))))))))) -> 600 | F7: =IF(AND('Retirement Dashboard'!$C$42="Yes", B7<= 'Retirement Dashboard'!$E$42), 600, 0) -> 600 | G7: =IF(B7<'Retirement Dashboard'!$E$6,IF(B7<=35,$BJ$4,IF(B7<=45,$BJ$5,IF(B7<=50,$BJ$6,IF(B7<=55,$BJ$7,IF(B7<=60,$BJ$8,IF(B7<=65,$BJ$9,IF(B7<=70,$BJ$10,$BJ$11)))))))*'Retirement Dashboard'!$C$12,0) -> 5878.264 | H7: =K6-C7-D7-E7-F7+G7 -> 54137.207 | I7: =$AL$8*H7 -> 2165.4883 | J7: =IF(I7+H7-$AL$35>0,I7+H7-$AL$35,0) -> 0 | K7: =H7+I7-J7 -> 56302.695 | M7: =IF(J7>=0,J7,0) -> 0 | N7: =IF(B7<$BH$31,IF(B8<=35,$BI$4,IF(B8<=45,$BI$5,IF(B8<=50,$BI$6,IF(B8<=55,$BI$7,IF(B8<=60,$BI$8,IF(B8<=65,$BI$9,IF(B8<=70,$BI$10,$BI$11)))))))*'Retirement Dashboard'!$C$12,0) -> 6439.776 | O7: =R6+N7+M7 -> 86451.394 | P7: =IF(B7<=55,$AL$5,$AN$6)*(IF(O7>=40000,40000,O7)) -> 2000 | Q7: =$AN$7*IF(O7>=40000,O7-40000,0) -> 2322.5697 | R7: =O7+P7+Q7 -> 90773.964 | T7: =IF(B7<$BH$31,IF(B7<=35,$BH$4,IF(B8<=45,$BH$5,IF(B8<=50,$BH$6,IF(B8<=55,$BH$7,IF(B8<=60,$BH$8,IF(B8<=65,$BH$9,IF(B8<=70,$BH$10,$BH$11)))))))*'Retirement Dashboard'!$C$12,0) -> 8401.96 | U7: =IF(B7<($BH$57+$BH$30),$BH$56*12,0) -> 0 | V7: =IF(B7<=34,$AN$31,IF(B7<=39,$AN$32,IF(B7<=44,$AN$33,IF(B7<=49,$AN$34,IF(B7<=54,$AN$35,IF(B7<=59,$AN$36,IF(B7<=69,$AN$37,0))))))) -> 188 | W7: =Z6+T7-U7-V7 -> 47731.186 | X7: =IF(B7<=55,$AL$3,$AN$3)*(IF(W7>=20000,20000,W7)) -> 700 | Y7: =$AL$4*IF(W7>=20000,W7-20000,W7) -> 693.27964 | Z7: =W7+X7+Y7 -> 49124.465 | AK7: BHS transferred to | AL7: SA | AM7: Next 10K RA | AN7: 0.05 | AR7: =AR6+1 -> 29 | AS7: =AS6+1 -> 2027 | AT7: 114100 | AU7: 228200 | AV7: 456400 | AW7: 900 | AX7: 1670 | AY7: 3550 | BA7: 32 | BB7: =(100%+$BB$3)*BB6 -> 263.2212 | BC7: =(100%+$BB$3)*BC6 -> 214.3224 | BD7: =(100%+$BD$3)*BD6 -> 688.7448 | BF7: Above 50-55 | BG7: =SUM(BH7:BJ7) -> 0.37 | BH7: =40.55%*BK7 -> 0.150035 | BI7: =31.08%*BK7 -> 0.114996 | BJ7: =28.37%*BK7 -> 0.104969 | BK7: =BL7+BM7 -> 0.37 | BL7: 0.17 | BM7: 0.2
B8: =B7+1 -> 55 | C8: =IF(B8>=67,$BI$55,C7+(1.0244%*C7)) -> 403.27671 | D8: =IF(B8<=20,$AL$14,IF(B8<=30,$AL$15,IF(B8<=40,$AL$16,IF(B8<=50,$AL$17,IF(B8<=60,$AL$18,IF(B8<=65,$AL$19,IF(B8<=70,$AL$20, IF(B8<=73,$AL$21,IF(B8<=75,$AL$22,IF(B8<=78,$AL$23,IF(B8<=80,$AL$24,IF(B8<=83,$AL$25,IF(B8<=85,$AL$26,IF(B8<=90,$AL$27,$AL$28)))))))))))))) -> 800 | E8: =IF(B8<=20,$AM$14,IF(B8<=30,$AM$15,IF(B8<=40,$AM$16,IF(B8<=50,$AM$17,IF(B8<=60,$AM$18,IF(B8<=65,$AM$19,IF(B8<=70,$AM$20, IF(B8<=73,$AM$21,IF(B8<=75,$AM$22,IF(B8<=78,$AM$23,IF(B8<=80,$AM$24,IF(B8<=83,$AM$25,IF(B8<=85,$AM$26,IF(B8<=90,$AM$27,$AM$28)))))))))))))) -> 600 | F8: =IF(AND('Retirement Dashboard'!$C$42="Yes", B8<= 'Retirement Dashboard'!$E$42), 600, 0) -> 600 | G8: =IF(B8<'Retirement Dashboard'!$E$6,IF(B8<=35,$BJ$4,IF(B8<=45,$BJ$5,IF(B8<=50,$BJ$6,IF(B8<=55,$BJ$7,IF(B8<=60,$BJ$8,IF(B8<=65,$BJ$9,IF(B8<=70,$BJ$10,$BJ$11)))))))*'Retirement Dashboard'!$C$12,0) -> 5878.264 | H8: =K7-C8-D8-E8-F8+G8 -> 59777.683 | I8: =$AL$8*H8 -> 2391.1073 | J8: =IF(I8+H8-$AL$35>0,I8+H8-$AL$35,0) -> 0 | K8: =H8+I8-J8 -> 62168.79 | M8: =IF(J8>=0,J8,0) -> 0 | N8: =IF(B8<$BH$31,IF(B9<=35,$BI$4,IF(B9<=45,$BI$5,IF(B9<=50,$BI$6,IF(B9<=55,$BI$7,IF(B9<=60,$BI$8,IF(B9<=65,$BI$9,IF(B9<=70,$BI$10,$BI$11)))))))*'Retirement Dashboard'!$C$12,0) -> 4988.62 | O8: =R7+N8+M8 -> 95762.584 | P8: =IF(B8<=55,$AL$5,$AN$6)*(IF(O8>=40000,40000,O8)) -> 2000 | Q8: =$AN$7*IF(O8>=40000,O8-40000,0) -> 2788.1292 | R8: =O8+P8+Q8 -> 100550.71 | T8: =IF(B8<$BH$31,IF(B8<=35,$BH$4,IF(B9<=45,$BH$5,IF(B9<=50,$BH$6,IF(B9<=55,$BH$7,IF(B9<=60,$BH$8,IF(B9<=65,$BH$9,IF(B9<=70,$BH$10,$BH$11)))))))*'Retirement Dashboard'!$C$12,0) -> 5618.704 | U8: =IF(B8<($BH$57+$BH$30),$BH$56*12,0) -> 0 | V8: =IF(B8<=34,$AN$31,IF(B8<=39,$AN$32,IF(B8<=44,$AN$33,IF(B8<=49,$AN$34,IF(B8<=54,$AN$35,IF(B8<=59,$AN$36,IF(B8<=69,$AN$37,0))))))) -> 298 | W8: =Z7+T8-U8-V8 -> 54445.169 | X8: =IF(B8<=55,$AL$3,$AN$3)*(IF(W8>=20000,20000,W8)) -> 700 | Y8: =$AL$4*IF(W8>=20000,W8-20000,W8) -> 861.12923 | Z8: =W8+X8+Y8 -> 56006.299 | AK8: MA | AL8: 0.04 | AM8: Remaining RA | AN8: 0.04 | AR8: =AR7+1 -> 30 | AS8: =AS7+1 -> 2028 | AT8: =(AT7*103.47%) -> 118059.27 | AU8: =AU7*103.5% -> 236187 | AV8: =AV7*103.5% -> 472374 | AW8: 930 | AX8: 1730 | AY8: =AY7*103.31% -> 3667.505 | BA8: 33 | BB8: =(100%+$BB$3)*BB7 -> 268.48562 | BC8: =(100%+$BB$3)*BC7 -> 218.60885 | BD8: =(100%+$BD$3)*BD7 -> 702.5197 | BF8: Above 55-60 | BG8: =SUM(BH8:BJ8) -> 0.299494 | BH8: =30.872%*BK8 -> 0.100334 | BI8: =27.41%*BK8 -> 0.0890825 | BJ8: =33.87%*BK8 -> 0.1100775 | BK8: =BL8+BM8 -> 0.325 | BL8: =32.5%-17% -> 0.155 | BM8: 0.17
B9: =B8+1 -> 56 | C9: =IF(B9>=67,$BI$55,C8+(1.0244%*C8)) -> 407.40787 | D9: =IF(B9<=20,$AL$14,IF(B9<=30,$AL$15,IF(B9<=40,$AL$16,IF(B9<=50,$AL$17,IF(B9<=60,$AL$18,IF(B9<=65,$AL$19,IF(B9<=70,$AL$20, IF(B9<=73,$AL$21,IF(B9<=75,$AL$22,IF(B9<=78,$AL$23,IF(B9<=80,$AL$24,IF(B9<=83,$AL$25,IF(B9<=85,$AL$26,IF(B9<=90,$AL$27,$AL$28)))))))))))))) -> 800 | E9: =IF(B9<=20,$AM$14,IF(B9<=30,$AM$15,IF(B9<=40,$AM$16,IF(B9<=50,$AM$17,IF(B9<=60,$AM$18,IF(B9<=65,$AM$19,IF(B9<=70,$AM$20, IF(B9<=73,$AM$21,IF(B9<=75,$AM$22,IF(B9<=78,$AM$23,IF(B9<=80,$AM$24,IF(B9<=83,$AM$25,IF(B9<=85,$AM$26,IF(B9<=90,$AM$27,$AM$28)))))))))))))) -> 600 | F9: =IF(AND('Retirement Dashboard'!$C$42="Yes", B9<= 'Retirement Dashboard'!$E$42), 600, 0) -> 600 | G9: =IF(B9<'Retirement Dashboard'!$E$6,IF(B9<=35,$BJ$4,IF(B9<=45,$BJ$5,IF(B9<=50,$BJ$6,IF(B9<=55,$BJ$7,IF(B9<=60,$BJ$8,IF(B9<=65,$BJ$9,IF(B9<=70,$BJ$10,$BJ$11)))))))*'Retirement Dashboard'!$C$12,0) -> 6164.34 | H9: =K8-C9-D9-E9-F9+G9 -> 65925.722 | I9: =$AL$8*H9 -> 2637.0289 | J9: =IF(I9+H9-$AL$35>0,I9+H9-$AL$35,0) -> 0 | K9: =H9+I9-J9 -> 68562.751 | M9: =IF(J9>=0,J9,0) -> 0 | N9: =IF(B9<$BH$31,IF(B10<=35,$BI$4,IF(B10<=45,$BI$5,IF(B10<=50,$BI$6,IF(B10<=55,$BI$7,IF(B10<=60,$BI$8,IF(B10<=65,$BI$9,IF(B10<=70,$BI$10,$BI$11)))))))*'Retirement Dashboard'!$C$12,0) -> 4988.62 | O9: =R8+N9+M9 -> 105539.33 | P9: =IF(B9<=55,$AL$5,$AN$6)*(IF(O9>=40000,40000,O9)) -> 2400 | Q9: =$AN$7*IF(O9>=40000,O9-40000,0) -> 3276.9666 | R9: =O9+P9+Q9 -> 111216.3 | T9: =IF(B9<$BH$31,IF(B9<=35,$BH$4,IF(B10<=45,$BH$5,IF(B10<=50,$BH$6,IF(B10<=55,$BH$7,IF(B10<=60,$BH$8,IF(B10<=65,$BH$9,IF(B10<=70,$BH$10,$BH$11)))))))*'Retirement Dashboard'!$C$12,0) -> 5618.704 | U9: =IF(B9<($BH$57+$BH$30),$BH$56*12,0) -> 0 | V9: =IF(B9<=34,$AN$31,IF(B9<=39,$AN$32,IF(B9<=44,$AN$33,IF(B9<=49,$AN$34,IF(B9<=54,$AN$35,IF(B9<=59,$AN$36,IF(B9<=69,$AN$37,0))))))) -> 298 | W9: =Z8+T9-U9-V9 -> 61327.003 | X9: =IF(B9<=55,$AL$3,$AN$3)*(IF(W9>=20000,20000,W9)) -> 1200 | Y9: =$AL$4*IF(W9>=20000,W9-20000,W9) -> 1033.1751 | Z9: =W9+X9+Y9 -> 63560.178 | AM9: BHS Transfer to | AN9: RA | AR9: =AR8+1 -> 31 | AS9: =AS8+1 -> 2029 | AT9: =(AT8*103.5%) -> 122191.34 | AU9: =AU8*103.5% -> 244453.54 | AV9: =AV8*103.5% -> 488907.09 | AW9: 950 | AX9: 1780 | AY9: =AY8*103.31% -> 3788.8994 | BA9: 34 | BB9: =(100%+$BB$3)*BB8 -> 273.85534 | BC9: =(100%+$BB$3)*BC8 -> 222.98102 | BD9: =(100%+$BD$3)*BD8 -> 716.57009 | BF9: Above 60-65 | BG9: =SUM(BH9:BJ9) -> 0.234295 | BH9: =15.62%*BK9 -> 0.036707 | BI9: =36.36%*BK9 -> 0.085446 | BJ9: =47.72%*BK9 -> 0.112142 | BK9: =BL9+BM9 -> 0.235 | BL9: =23.5%-BM9 -> 0.12 | BM9: 0.115
B10: =B9+1 -> 57 | C10: =IF(B10>=67,$BI$55,C9+(1.0244%*C9)) -> 411.58136 | D10: =IF(B10<=20,$AL$14,IF(B10<=30,$AL$15,IF(B10<=40,$AL$16,IF(B10<=50,$AL$17,IF(B10<=60,$AL$18,IF(B10<=65,$AL$19,IF(B10<=70,$AL$20, IF(B10<=73,$AL$21,IF(B10<=75,$AL$22,IF(B10<=78,$AL$23,IF(B10<=80,$AL$24,IF(B10<=83,$AL$25,IF(B10<=85,$AL$26,IF(B10<=90,$AL$27,$AL$28)))))))))))))) -> 800 | E10: =IF(B10<=20,$AM$14,IF(B10<=30,$AM$15,IF(B10<=40,$AM$16,IF(B10<=50,$AM$17,IF(B10<=60,$AM$18,IF(B10<=65,$AM$19,IF(B10<=70,$AM$20, IF(B10<=73,$AM$21,IF(B10<=75,$AM$22,IF(B10<=78,$AM$23,IF(B10<=80,$AM$24,IF(B10<=83,$AM$25,IF(B10<=85,$AM$26,IF(B10<=90,$AM$27,$AM$28)))))))))))))) -> 600 | F10: =IF(AND('Retirement Dashboard'!$C$42="Yes", B10<= 'Retirement Dashboard'!$E$42), 600, 0) -> 600 | G10: =IF(B10<'Retirement Dashboard'!$E$6,IF(B10<=35,$BJ$4,IF(B10<=45,$BJ$5,IF(B10<=50,$BJ$6,IF(B10<=55,$BJ$7,IF(B10<=60,$BJ$8,IF(B10<=65,$BJ$9,IF(B10<=70,$BJ$10,$BJ$11)))))))*'Retirement Dashboard'!$C$12,0) -> 6164.34 | H10: =K9-C10-D10-E10-F10+G10 -> 72315.509 | I10: =$AL$8*H10 -> 2892.6204 | J10: =IF(I10+H10-$AL$35>0,I10+H10-$AL$35,0) -> 0 | K10: =H10+I10-J10 -> 75208.13 | M10: =IF(J10>=0,J10,0) -> 0 | N10: =IF(B10<$BH$31,IF(B11<=35,$BI$4,IF(B11<=45,$BI$5,IF(B11<=50,$BI$6,IF(B11<=55,$BI$7,IF(B11<=60,$BI$8,IF(B11<=65,$BI$9,IF(B11<=70,$BI$10,$BI$11)))))))*'Retirement Dashboard'!$C$12,0) -> 4988.62 | O10: =R9+N10+M10 -> 116204.92 | P10: =IF(B10<=55,$AL$5,$AN$6)*(IF(O10>=40000,40000,O10)) -> 2400 | Q10: =$AN$7*IF(O10>=40000,O10-40000,0) -> 3810.246 | R10: =O10+P10+Q10 -> 122415.17 | T10: =IF(B10<$BH$31,IF(B10<=35,$BH$4,IF(B11<=45,$BH$5,IF(B11<=50,$BH$6,IF(B11<=55,$BH$7,IF(B11<=60,$BH$8,IF(B11<=65,$BH$9,IF(B11<=70,$BH$10,$BH$11)))))))*'Retirement Dashboard'!$C$12,0) -> 5618.704 | U10: =IF(B10<($BH$57+$BH$30),$BH$56*12,0) -> 0 | V10: =IF(B10<=34,$AN$31,IF(B10<=39,$AN$32,IF(B10<=44,$AN$33,IF(B10<=49,$AN$34,IF(B10<=54,$AN$35,IF(B10<=59,$AN$36,IF(B10<=69,$AN$37,0))))))) -> 298 | W10: =Z9+T10-U10-V10 -> 68880.882 | X10: =IF(B10<=55,$AL$3,$AN$3)*(IF(W10>=20000,20000,W10)) -> 1200 | Y10: =$AL$4*IF(W10>=20000,W10-20000,W10) -> 1222.022 | Z10: =W10+X10+Y10 -> 71302.904 | AM10: MA | AN10: 0.04 | AR10: =AR9+1 -> 32 | AS10: =AS9+1 -> 2030 | AT10: =(AT9*103.5%) -> 126468.04 | AU10: =AU9*103.5% -> 253009.42 | AV10: =AV9*103.5% -> 506018.84 | AW10: 980 | AX10: 1840 | AY10: =AY9*103.31% -> 3914.312 | BA10: 35 | BB10: =(100%+$BB$3)*BB9 -> 279.33244 | BC10: =(100%+$BB$3)*BC9 -> 227.44065 | BD10: =(100%+$BD$3)*BD9 -> 730.90149 | BF10: Above 65 -70 | BG10: =SUM(BH10:BJ10) -> 0.165 | BH10: =6.07%*BK10 -> 0.0100155 | BI10: =30.3%*BK10 -> 0.049995 | BJ10: =63.63%*BK10 -> 0.1049895 | BK10: =BL10+BM10 -> 0.165 | BL10: =16.5%-BM10 -> 0.09 | BM10: 0.075
B11: =B10+1 -> 58 | C11: =IF(B11>=67,$BI$55,C10+(1.0244%*C10)) -> 415.7976 | D11: =IF(B11<=20,$AL$14,IF(B11<=30,$AL$15,IF(B11<=40,$AL$16,IF(B11<=50,$AL$17,IF(B11<=60,$AL$18,IF(B11<=65,$AL$19,IF(B11<=70,$AL$20, IF(B11<=73,$AL$21,IF(B11<=75,$AL$22,IF(B11<=78,$AL$23,IF(B11<=80,$AL$24,IF(B11<=83,$AL$25,IF(B11<=85,$AL$26,IF(B11<=90,$AL$27,$AL$28)))))))))))))) -> 800 | E11: =IF(B11<=20,$AM$14,IF(B11<=30,$AM$15,IF(B11<=40,$AM$16,IF(B11<=50,$AM$17,IF(B11<=60,$AM$18,IF(B11<=65,$AM$19,IF(B11<=70,$AM$20, IF(B11<=73,$AM$21,IF(B11<=75,$AM$22,IF(B11<=78,$AM$23,IF(B11<=80,$AM$24,IF(B11<=83,$AM$25,IF(B11<=85,$AM$26,IF(B11<=90,$AM$27,$AM$28)))))))))))))) -> 600 | F11: =IF(AND('Retirement Dashboard'!$C$42="Yes", B11<= 'Retirement Dashboard'!$E$42), 600, 0) -> 600 | G11: =IF(B11<'Retirement Dashboard'!$E$6,IF(B11<=35,$BJ$4,IF(B11<=45,$BJ$5,IF(B11<=50,$BJ$6,IF(B11<=55,$BJ$7,IF(B11<=60,$BJ$8,IF(B11<=65,$BJ$9,IF(B11<=70,$BJ$10,$BJ$11)))))))*'Retirement Dashboard'!$C$12,0) -> 6164.34 | H11: =K10-C11-D11-E11-F11+G11 -> 78956.672 | I11: =$AL$8*H11 -> 3158.2669 | J11: =IF(I11+H11-$AL$35>0,I11+H11-$AL$35,0) -> 6614.9392 | K11: =H11+I11-J11 -> 75500 | M11: =IF(J11>=0,J11,0) -> 6614.9392 | N11: =IF(B11<$BH$31,IF(B12<=35,$BI$4,IF(B12<=45,$BI$5,IF(B12<=50,$BI$6,IF(B12<=55,$BI$7,IF(B12<=60,$BI$8,IF(B12<=65,$BI$9,IF(B12<=70,$BI$10,$BI$11)))))))*'Retirement Dashboard'!$C$12,0) -> 4988.62 | O11: =R10+N11+M11 -> 134018.72 | P11: =IF(B11<=55,$AL$5,$AN$6)*(IF(O11>=40000,40000,O11)) -> 2400 | Q11: =$AN$7*IF(O11>=40000,O11-40000,0) -> 4700.9362 | R11: =O11+P11+Q11 -> 141119.66 | T11: =IF(B11<$BH$31,IF(B11<=35,$BH$4,IF(B12<=45,$BH$5,IF(B12<=50,$BH$6,IF(B12<=55,$BH$7,IF(B12<=60,$BH$8,IF(B12<=65,$BH$9,IF(B12<=70,$BH$10,$BH$11)))))))*'Retirement Dashboard'!$C$12,0) -> 5618.704 | U11: =IF(B11<($BH$57+$BH$30),$BH$56*12,0) -> 0 | V11: =IF(B11<=34,$AN$31,IF(B11<=39,$AN$32,IF(B11<=44,$AN$33,IF(B11<=49,$AN$34,IF(B11<=54,$AN$35,IF(B11<=59,$AN$36,IF(B11<=69,$AN$37,0))))))) -> 298 | W11: =Z10+T11-U11-V11 -> 76623.608 | X11: =IF(B11<=55,$AL$3,$AN$3)*(IF(W11>=20000,20000,W11)) -> 1200 | Y11: =$AL$4*IF(W11>=20000,W11-20000,W11) -> 1415.5902 | Z11: =W11+X11+Y11 -> 79239.198 | AR11: =AR10+1 -> 33 | AS11: =AS10+1 -> 2031 | AT11: =(AT10*103.5%) -> 130894.42 | AU11: =AU10*103.5% -> 261864.75 | AV11: =AV10*103.5% -> 523729.5 | AW11: =AW10+30 -> 1010 | AX11: =AX10+60 -> 1900 | AY11: =AY10*103.31% -> 4043.8757 | BA11: 36 | BB11: =(100%+$BB$3)*BB10 -> 284.91909 | BC11: =(100%+$BB$3)*BC10 -> 231.98946 | BD11: =(100%+$BD$3)*BD10 -> 745.51952 | BF11: Above 70 | BG11: =SUM(BH11:BJ11) -> 0.125 | BH11: =8%*BK11 -> 0.01 | BI11: =8%*BK11 -> 0.01 | BJ11: =84%*BK11 -> 0.105 | BK11: =BL11+BM11 -> 0.125 | BL11: =12.5%-BM11 -> 0.075 | BM11: 0.05
B12: =B11+1 -> 59 | C12: =IF(B12>=67,$BI$55,C11+(1.0244%*C11)) -> 420.05703 | D12: =IF(B12<=20,$AL$14,IF(B12<=30,$AL$15,IF(B12<=40,$AL$16,IF(B12<=50,$AL$17,IF(B12<=60,$AL$18,IF(B12<=65,$AL$19,IF(B12<=70,$AL$20, IF(B12<=73,$AL$21,IF(B12<=75,$AL$22,IF(B12<=78,$AL$23,IF(B12<=80,$AL$24,IF(B12<=83,$AL$25,IF(B12<=85,$AL$26,IF(B12<=90,$AL$27,$AL$28)))))))))))))) -> 800 | E12: =IF(B12<=20,$AM$14,IF(B12<=30,$AM$15,IF(B12<=40,$AM$16,IF(B12<=50,$AM$17,IF(B12<=60,$AM$18,IF(B12<=65,$AM$19,IF(B12<=70,$AM$20, IF(B12<=73,$AM$21,IF(B12<=75,$AM$22,IF(B12<=78,$AM$23,IF(B12<=80,$AM$24,IF(B12<=83,$AM$25,IF(B12<=85,$AM$26,IF(B12<=90,$AM$27,$AM$28)))))))))))))) -> 600 | F12: =IF(AND('Retirement Dashboard'!$C$42="Yes", B12<= 'Retirement Dashboard'!$E$42), 600, 0) -> 600 | G12: =IF(B12<'Retirement Dashboard'!$E$6,IF(B12<=35,$BJ$4,IF(B12<=45,$BJ$5,IF(B12<=50,$BJ$6,IF(B12<=55,$BJ$7,IF(B12<=60,$BJ$8,IF(B12<=65,$BJ$9,IF(B12<=70,$BJ$10,$BJ$11)))))))*'Retirement Dashboard'!$C$12,0) -> 6164.34 | H12: =K11-C12-D12-E12-F12+G12 -> 79244.283 | I12: =$AL$8*H12 -> 3169.7713 | J12: =IF(I12+H12-$AL$35>0,I12+H12-$AL$35,0) -> 6914.0543 | K12: =H12+I12-J12 -> 75500 | M12: =IF(J12>=0,J12,0) -> 6914.0543 | N12: =IF(B12<$BH$31,IF(B13<=35,$BI$4,IF(B13<=45,$BI$5,IF(B13<=50,$BI$6,IF(B13<=55,$BI$7,IF(B13<=60,$BI$8,IF(B13<=65,$BI$9,IF(B13<=70,$BI$10,$BI$11)))))))*'Retirement Dashboard'!$C$12,0) -> 4988.62 | O12: =R11+N12+M12 -> 153022.33 | P12: =IF(B12<=55,$AL$5,$AN$6)*(IF(O12>=40000,40000,O12)) -> 2400 | Q12: =$AN$7*IF(O12>=40000,O12-40000,0) -> 5651.1167 | R12: =O12+P12+Q12 -> 161073.45 | T12: =IF(B12<$BH$31,IF(B12<=35,$BH$4,IF(B13<=45,$BH$5,IF(B13<=50,$BH$6,IF(B13<=55,$BH$7,IF(B13<=60,$BH$8,IF(B13<=65,$BH$9,IF(B13<=70,$BH$10,$BH$11)))))))*'Retirement Dashboard'!$C$12,0) -> 5618.704 | U12: =IF(B12<($BH$57+$BH$30),$BH$56*12,0) -> 0 | V12: =IF(B12<=34,$AN$31,IF(B12<=39,$AN$32,IF(B12<=44,$AN$33,IF(B12<=49,$AN$34,IF(B12<=54,$AN$35,IF(B12<=59,$AN$36,IF(B12<=69,$AN$37,0))))))) -> 298 | W12: =Z11+T12-U12-V12 -> 84559.902 | X12: =IF(B12<=55,$AL$3,$AN$3)*(IF(W12>=20000,20000,W12)) -> 1200 | Y12: =$AL$4*IF(W12>=20000,W12-20000,W12) -> 1613.9975 | Z12: =W12+X12+Y12 -> 87373.899 | AK12: H&S | AR12: =AR11+1 -> 34 | AS12: =AS11+1 -> 2032 | AT12: =(AT11*103.5%) -> 135475.73 | AU12: =AU11*103.5% -> 271030.01 | AV12: =AV11*103.5% -> 542060.03 | AW12: =AW11+30 -> 1040 | AX12: =AX11+60 -> 1960 | AY12: =AY11*103.31% -> 4177.728 | BA12: 37 | BB12: =(100%+$BB$3)*BB11 -> 290.61747 | BC12: =(100%+$BB$3)*BC11 -> 236.62925 | BD12: =(100%+$BD$3)*BD11 -> 760.42991
B13: =B12+1 -> 60 | C13: =IF(B13>=67,$BI$55,C12+(1.0244%*C12)) -> 424.3601 | D13: =IF(B13<=20,$AL$14,IF(B13<=30,$AL$15,IF(B13<=40,$AL$16,IF(B13<=50,$AL$17,IF(B13<=60,$AL$18,IF(B13<=65,$AL$19,IF(B13<=70,$AL$20, IF(B13<=73,$AL$21,IF(B13<=75,$AL$22,IF(B13<=78,$AL$23,IF(B13<=80,$AL$24,IF(B13<=83,$AL$25,IF(B13<=85,$AL$26,IF(B13<=90,$AL$27,$AL$28)))))))))))))) -> 800 | E13: =IF(B13<=20,$AM$14,IF(B13<=30,$AM$15,IF(B13<=40,$AM$16,IF(B13<=50,$AM$17,IF(B13<=60,$AM$18,IF(B13<=65,$AM$19,IF(B13<=70,$AM$20, IF(B13<=73,$AM$21,IF(B13<=75,$AM$22,IF(B13<=78,$AM$23,IF(B13<=80,$AM$24,IF(B13<=83,$AM$25,IF(B13<=85,$AM$26,IF(B13<=90,$AM$27,$AM$28)))))))))))))) -> 600 | F13: =IF(AND('Retirement Dashboard'!$C$42="Yes", B13<= 'Retirement Dashboard'!$E$42), 600, 0) -> 600 | G13: =IF(B13<'Retirement Dashboard'!$E$6,IF(B13<=35,$BJ$4,IF(B13<=45,$BJ$5,IF(B13<=50,$BJ$6,IF(B13<=55,$BJ$7,IF(B13<=60,$BJ$8,IF(B13<=65,$BJ$9,IF(B13<=70,$BJ$10,$BJ$11)))))))*'Retirement Dashboard'!$C$12,0) -> 6164.34 | H13: =K12-C13-D13-E13-F13+G13 -> 79239.98 | I13: =$AL$8*H13 -> 3169.5992 | J13: =IF(I13+H13-$AL$35>0,I13+H13-$AL$35,0) -> 6909.5791 | K13: =H13+I13-J13 -> 75500 | M13: =IF(J13>=0,J13,0) -> 6909.5791 | N13: =IF(B13<$BH$31,IF(B14<=35,$BI$4,IF(B14<=45,$BI$5,IF(B14<=50,$BI$6,IF(B14<=55,$BI$7,IF(B14<=60,$BI$8,IF(B14<=65,$BI$9,IF(B14<=70,$BI$10,$BI$11)))))))*'Retirement Dashboard'!$C$12,0) -> 4784.976 | O13: =R12+N13+M13 -> 172768.01 | P13: =IF(B13<=55,$AL$5,$AN$6)*(IF(O13>=40000,40000,O13)) -> 2400 | Q13: =$AN$7*IF(O13>=40000,O13-40000,0) -> 6638.4003 | R13: =O13+P13+Q13 -> 181806.41 | T13: =IF(B13<$BH$31,IF(B13<=35,$BH$4,IF(B14<=45,$BH$5,IF(B14<=50,$BH$6,IF(B14<=55,$BH$7,IF(B14<=60,$BH$8,IF(B14<=65,$BH$9,IF(B14<=70,$BH$10,$BH$11)))))))*'Retirement Dashboard'!$C$12,0) -> 2055.592 | U13: =IF(B13<($BH$57+$BH$30),$BH$56*12,0) -> 0 | V13: =IF(B13<=34,$AN$31,IF(B13<=39,$AN$32,IF(B13<=44,$AN$33,IF(B13<=49,$AN$34,IF(B13<=54,$AN$35,IF(B13<=59,$AN$36,IF(B13<=69,$AN$37,0))))))) -> 298 | W13: =Z12+T13-U13-V13 -> 89131.491 | X13: =IF(B13<=55,$AL$3,$AN$3)*(IF(W13>=20000,20000,W13)) -> 1200 | Y13: =$AL$4*IF(W13>=20000,W13-20000,W13) -> 1728.2873 | Z13: =W13+X13+Y13 -> 92059.779 | AK13: Age | AL13: Medishield | AM13: Private Shield CPF Limit | AR13: =AR12+1 -> 35 | AS13: =AS12+1 -> 2033 | AT13: =(AT12*103.5%) -> 140217.38 | AU13: =AU12*103.5% -> 280516.07 | AV13: =AV12*103.5% -> 561032.13 | AW13: =AW12+30 -> 1070 | AX13: =AX12+60 -> 2020 | AY13: =AY12*103.31% -> 4316.0108 | BA13: 38 | BB13: =(100%+$BB$3)*BB12 -> 296.42982 | BC13: =(100%+$BB$3)*BC12 -> 241.36183 | BD13: =(100%+$BD$3)*BD12 -> 775.63851
B14: =B13+1 -> 61 | C14: =IF(B14>=67,$BI$55,C13+(1.0244%*C13)) -> 428.70724 | D14: =IF(B14<=20,$AL$14,IF(B14<=30,$AL$15,IF(B14<=40,$AL$16,IF(B14<=50,$AL$17,IF(B14<=60,$AL$18,IF(B14<=65,$AL$19,IF(B14<=70,$AL$20, IF(B14<=73,$AL$21,IF(B14<=75,$AL$22,IF(B14<=78,$AL$23,IF(B14<=80,$AL$24,IF(B14<=83,$AL$25,IF(B14<=85,$AL$26,IF(B14<=90,$AL$27,$AL$28)))))))))))))) -> 1020 | E14: =IF(B14<=20,$AM$14,IF(B14<=30,$AM$15,IF(B14<=40,$AM$16,IF(B14<=50,$AM$17,IF(B14<=60,$AM$18,IF(B14<=65,$AM$19,IF(B14<=70,$AM$20, IF(B14<=73,$AM$21,IF(B14<=75,$AM$22,IF(B14<=78,$AM$23,IF(B14<=80,$AM$24,IF(B14<=83,$AM$25,IF(B14<=85,$AM$26,IF(B14<=90,$AM$27,$AM$28)))))))))))))) -> 600 | F14: =IF(AND('Retirement Dashboard'!$C$42="Yes", B14<= 'Retirement Dashboard'!$E$42), 600, 0) -> 600 | G14: =IF(B14<'Retirement Dashboard'!$E$6,IF(B14<=35,$BJ$4,IF(B14<=45,$BJ$5,IF(B14<=50,$BJ$6,IF(B14<=55,$BJ$7,IF(B14<=60,$BJ$8,IF(B14<=65,$BJ$9,IF(B14<=70,$BJ$10,$BJ$11)))))))*'Retirement Dashboard'!$C$12,0) -> 6279.952 | H14: =K13-C14-D14-E14-F14+G14 -> 79131.245 | I14: =$AL$8*H14 -> 3165.2498 | J14: =IF(I14+H14-$AL$35>0,I14+H14-$AL$35,0) -> 6796.4946 | K14: =H14+I14-J14 -> 75500 | M14: =IF(J14>=0,J14,0) -> 6796.4946 | N14: =IF(B14<$BH$31,IF(B15<=35,$BI$4,IF(B15<=45,$BI$5,IF(B15<=50,$BI$6,IF(B15<=55,$BI$7,IF(B15<=60,$BI$8,IF(B15<=65,$BI$9,IF(B15<=70,$BI$10,$BI$11)))))))*'Retirement Dashboard'!$C$12,0) -> 4784.976 | O14: =R13+N14+M14 -> 193387.88 | P14: =IF(B14<=55,$AL$5,$AN$6)*(IF(O14>=40000,40000,O14)) -> 2400 | Q14: =$AN$7*IF(O14>=40000,O14-40000,0) -> 7669.3939 | R14: =O14+P14+Q14 -> 203457.27 | T14: =IF(B14<$BH$31,IF(B14<=35,$BH$4,IF(B15<=45,$BH$5,IF(B15<=50,$BH$6,IF(B15<=55,$BH$7,IF(B15<=60,$BH$8,IF(B15<=65,$BH$9,IF(B15<=70,$BH$10,$BH$11)))))))*'Retirement Dashboard'!$C$12,0) -> 2055.592 | U14: =IF(B14<($BH$57+$BH$30),$BH$56*12,0) -> 0 | V14: =IF(B14<=34,$AN$31,IF(B14<=39,$AN$32,IF(B14<=44,$AN$33,IF(B14<=49,$AN$34,IF(B14<=54,$AN$35,IF(B14<=59,$AN$36,IF(B14<=69,$AN$37,0))))))) -> 298 | W14: =Z13+T14-U14-V14 -> 93817.371 | X14: =IF(B14<=55,$AL$3,$AN$3)*(IF(W14>=20000,20000,W14)) -> 1200 | Y14: =$AL$4*IF(W14>=20000,W14-20000,W14) -> 1845.4343 | Z14: =W14+X14+Y14 -> 96862.805 | AK14: <=20 | AL14: 145 | AM14: 300 | AR14: =AR13+1 -> 36 | AS14: =AS13+1 -> 2034 | AT14: =(AT13*103.5%) -> 145124.99 | AU14: =AU13*103.5% -> 290334.13 | AV14: =AV13*103.5% -> 580668.26 | AW14: =AW13+30 -> 1100 | AX14: =AX13+60 -> 2080 | AY14: =AY13*103.31% -> 4458.8708 | BA14: 39 | BB14: =(100%+$BB$3)*BB13 -> 302.35842 | BC14: =(100%+$BB$3)*BC13 -> 246.18907 | BD14: =(100%+$BD$3)*BD13 -> 791.15128
B15: =B14+1 -> 62 | C15: =IF(B15>=67,$BI$55,C14+(1.0244%*C14)) -> 433.09892 | D15: =IF(B15<=20,$AL$14,IF(B15<=30,$AL$15,IF(B15<=40,$AL$16,IF(B15<=50,$AL$17,IF(B15<=60,$AL$18,IF(B15<=65,$AL$19,IF(B15<=70,$AL$20, IF(B15<=73,$AL$21,IF(B15<=75,$AL$22,IF(B15<=78,$AL$23,IF(B15<=80,$AL$24,IF(B15<=83,$AL$25,IF(B15<=85,$AL$26,IF(B15<=90,$AL$27,$AL$28)))))))))))))) -> 1020 | E15: =IF(B15<=20,$AM$14,IF(B15<=30,$AM$15,IF(B15<=40,$AM$16,IF(B15<=50,$AM$17,IF(B15<=60,$AM$18,IF(B15<=65,$AM$19,IF(B15<=70,$AM$20, IF(B15<=73,$AM$21,IF(B15<=75,$AM$22,IF(B15<=78,$AM$23,IF(B15<=80,$AM$24,IF(B15<=83,$AM$25,IF(B15<=85,$AM$26,IF(B15<=90,$AM$27,$AM$28)))))))))))))) -> 600 | F15: =IF(AND('Retirement Dashboard'!$C$42="Yes", B15<= 'Retirement Dashboard'!$E$42), 600, 0) -> 600 | G15: =IF(B15<'Retirement Dashboard'!$E$6,IF(B15<=35,$BJ$4,IF(B15<=45,$BJ$5,IF(B15<=50,$BJ$6,IF(B15<=55,$BJ$7,IF(B15<=60,$BJ$8,IF(B15<=65,$BJ$9,IF(B15<=70,$BJ$10,$BJ$11)))))))*'Retirement Dashboard'!$C$12,0) -> 6279.952 | H15: =K14-C15-D15-E15-F15+G15 -> 79126.853 | I15: =$AL$8*H15 -> 3165.0741 | J15: =IF(I15+H15-$AL$35>0,I15+H15-$AL$35,0) -> 6791.9272 | K15: =H15+I15-J15 -> 75500 | M15: =IF(J15>=0,J15,0) -> 6791.9272 | N15: =IF(B15<$BH$31,IF(B16<=35,$BI$4,IF(B16<=45,$BI$5,IF(B16<=50,$BI$6,IF(B16<=55,$BI$7,IF(B16<=60,$BI$8,IF(B16<=65,$BI$9,IF(B16<=70,$BI$10,$BI$11)))))))*'Retirement Dashboard'!$C$12,0) -> 4784.976 | O15: =R14+N15+M15 -> 215034.17 | P15: =IF(B15<=55,$AL$5,$AN$6)*(IF(O15>=40000,40000,O15)) -> 2400 | Q15: =$AN$7*IF(O15>=40000,O15-40000,0) -> 8751.7087 | R15: =O15+P15+Q15 -> 226185.88 | T15: =IF(B15<$BH$31,IF(B15<=35,$BH$4,IF(B16<=45,$BH$5,IF(B16<=50,$BH$6,IF(B16<=55,$BH$7,IF(B16<=60,$BH$8,IF(B16<=65,$BH$9,IF(B16<=70,$BH$10,$BH$11)))))))*'Retirement Dashboard'!$C$12,0) -> 2055.592 | U15: =IF(B15<($BH$57+$BH$30),$BH$56*12,0) -> 0 | V15: =IF(B15<=34,$AN$31,IF(B15<=39,$AN$32,IF(B15<=44,$AN$33,IF(B15<=49,$AN$34,IF(B15<=54,$AN$35,IF(B15<=59,$AN$36,IF(B15<=69,$AN$37,0))))))) -> 298 | W15: =Z14+T15-U15-V15 -> 98620.397 | X15: =IF(B15<=55,$AL$3,$AN$3)*(IF(W15>=20000,20000,W15)) -> 1200 | Y15: =$AL$4*IF(W15>=20000,W15-20000,W15) -> 1965.5099 | Z15: =W15+X15+Y15 -> 101785.91 | AK15: <=30 | AL15: 250 | AM15: 300 | AR15: =AR14+1 -> 37 | AS15: =AS14+1 -> 2035 | AT15: =(AT14*103.5%) -> 150204.36 | AU15: =AU14*103.5% -> 300495.82 | AV15: =AV14*103.5% -> 600991.64 | AW15: =AW14+30 -> 1130 | AX15: =AX14+60 -> 2140 | AY15: =AY14*103.31% -> 4606.4594 | BA15: 40 | BB15: =(100%+$BB$3)*BB14 -> 308.40559 | BC15: =(100%+$BB$3)*BC14 -> 251.11285 | BD15: =(100%+$BD$3)*BD14 -> 806.97431
B16: =B15+1 -> 63 | C16: =IF(B16>=67,$BI$55,C15+(1.0244%*C15)) -> 437.53558 | D16: =IF(B16<=20,$AL$14,IF(B16<=30,$AL$15,IF(B16<=40,$AL$16,IF(B16<=50,$AL$17,IF(B16<=60,$AL$18,IF(B16<=65,$AL$19,IF(B16<=70,$AL$20, IF(B16<=73,$AL$21,IF(B16<=75,$AL$22,IF(B16<=78,$AL$23,IF(B16<=80,$AL$24,IF(B16<=83,$AL$25,IF(B16<=85,$AL$26,IF(B16<=90,$AL$27,$AL$28)))))))))))))) -> 1020 | E16: =IF(B16<=20,$AM$14,IF(B16<=30,$AM$15,IF(B16<=40,$AM$16,IF(B16<=50,$AM$17,IF(B16<=60,$AM$18,IF(B16<=65,$AM$19,IF(B16<=70,$AM$20, IF(B16<=73,$AM$21,IF(B16<=75,$AM$22,IF(B16<=78,$AM$23,IF(B16<=80,$AM$24,IF(B16<=83,$AM$25,IF(B16<=85,$AM$26,IF(B16<=90,$AM$27,$AM$28)))))))))))))) -> 600 | F16: =IF(AND('Retirement Dashboard'!$C$42="Yes", B16<= 'Retirement Dashboard'!$E$42), 600, 0) -> 600 | G16: =IF(B16<'Retirement Dashboard'!$E$6,IF(B16<=35,$BJ$4,IF(B16<=45,$BJ$5,IF(B16<=50,$BJ$6,IF(B16<=55,$BJ$7,IF(B16<=60,$BJ$8,IF(B16<=65,$BJ$9,IF(B16<=70,$BJ$10,$BJ$11)))))))*'Retirement Dashboard'!$C$12,0) -> 6279.952 | H16: =K15-C16-D16-E16-F16+G16 -> 79122.416 | I16: =$AL$8*H16 -> 3164.8967 | J16: =IF(I16+H16-$AL$35>0,I16+H16-$AL$35,0) -> 6787.3131 | K16: =H16+I16-J16 -> 75500 | M16: =IF(J16>=0,J16,0) -> 6787.3131 | N16: =IF(B16<$BH$31,IF(B17<=35,$BI$4,IF(B17<=45,$BI$5,IF(B17<=50,$BI$6,IF(B17<=55,$BI$7,IF(B17<=60,$BI$8,IF(B17<=65,$BI$9,IF(B17<=70,$BI$10,$BI$11)))))))*'Retirement Dashboard'!$C$12,0) -> 4784.976 | O16: =R15+N16+M16 -> 237758.17 | P16: =IF(B16<=55,$AL$5,$AN$6)*(IF(O16>=40000,40000,O16)) -> 2400 | Q16: =$AN$7*IF(O16>=40000,O16-40000,0) -> 9887.9086 | R16: =O16+P16+Q16 -> 250046.08 | T16: =IF(B16<$BH$31,IF(B16<=35,$BH$4,IF(B17<=45,$BH$5,IF(B17<=50,$BH$6,IF(B17<=55,$BH$7,IF(B17<=60,$BH$8,IF(B17<=65,$BH$9,IF(B17<=70,$BH$10,$BH$11)))))))*'Retirement Dashboard'!$C$12,0) -> 2055.592 | U16: =IF(B16<($BH$57+$BH$30),$BH$56*12,0) -> 0 | V16: =IF(B16<=34,$AN$31,IF(B16<=39,$AN$32,IF(B16<=44,$AN$33,IF(B16<=49,$AN$34,IF(B16<=54,$AN$35,IF(B16<=59,$AN$36,IF(B16<=69,$AN$37,0))))))) -> 298 | W16: =Z15+T16-U16-V16 -> 103543.5 | X16: =IF(B16<=55,$AL$3,$AN$3)*(IF(W16>=20000,20000,W16)) -> 1200 | Y16: =$AL$4*IF(W16>=20000,W16-20000,W16) -> 2088.5875 | Z16: =W16+X16+Y16 -> 106832.09 | AK16: <=40 | AL16: 390 | AM16: 300 | AR16: =AR15+1 -> 38 | AS16: =AS15+1 -> 2036 | AT16: =(AT15*103.5%) -> 155461.51 | AU16: =AU15*103.5% -> 311013.18 | AV16: =AV15*103.5% -> 622026.35 | AW16: =AW15+30 -> 1160 | AX16: =AX15+60 -> 2200 | AY16: =AY15*103.31% -> 4758.9332 | BA16: 41 | BB16: =(100%+$BB$3)*BB15 -> 314.5737 | BC16: =(100%+$BB$3)*BC15 -> 256.13511 | BD16: =(100%+$BD$3)*BD15 -> 823.11379
B17: =B16+1 -> 64 | C17: =IF(B17>=67,$BI$55,C16+(1.0244%*C16)) -> 442.0177 | D17: =IF(B17<=20,$AL$14,IF(B17<=30,$AL$15,IF(B17<=40,$AL$16,IF(B17<=50,$AL$17,IF(B17<=60,$AL$18,IF(B17<=65,$AL$19,IF(B17<=70,$AL$20, IF(B17<=73,$AL$21,IF(B17<=75,$AL$22,IF(B17<=78,$AL$23,IF(B17<=80,$AL$24,IF(B17<=83,$AL$25,IF(B17<=85,$AL$26,IF(B17<=90,$AL$27,$AL$28)))))))))))))) -> 1020 | E17: =IF(B17<=20,$AM$14,IF(B17<=30,$AM$15,IF(B17<=40,$AM$16,IF(B17<=50,$AM$17,IF(B17<=60,$AM$18,IF(B17<=65,$AM$19,IF(B17<=70,$AM$20, IF(B17<=73,$AM$21,IF(B17<=75,$AM$22,IF(B17<=78,$AM$23,IF(B17<=80,$AM$24,IF(B17<=83,$AM$25,IF(B17<=85,$AM$26,IF(B17<=90,$AM$27,$AM$28)))))))))))))) -> 600 | F17: =IF(AND('Retirement Dashboard'!$C$42="Yes", B17<= 'Retirement Dashboard'!$E$42), 600, 0) -> 600 | G17: =IF(B17<'Retirement Dashboard'!$E$6,IF(B17<=35,$BJ$4,IF(B17<=45,$BJ$5,IF(B17<=50,$BJ$6,IF(B17<=55,$BJ$7,IF(B17<=60,$BJ$8,IF(B17<=65,$BJ$9,IF(B17<=70,$BJ$10,$BJ$11)))))))*'Retirement Dashboard'!$C$12,0) -> 6279.952 | H17: =K16-C17-D17-E17-F17+G17 -> 79117.934 | I17: =$AL$8*H17 -> 3164.7174 | J17: =IF(I17+H17-$AL$35>0,I17+H17-$AL$35,0) -> 6782.6517 | K17: =H17+I17-J17 -> 75500 | M17: =IF(J17>=0,J17,0) -> 6782.6517 | N17: =IF(B17<$BH$31,IF(B18<=35,$BI$4,IF(B18<=45,$BI$5,IF(B18<=50,$BI$6,IF(B18<=55,$BI$7,IF(B18<=60,$BI$8,IF(B18<=65,$BI$9,IF(B18<=70,$BI$10,$BI$11)))))))*'Retirement Dashboard'!$C$12,0) -> 4784.976 | O17: =R16+N17+M17 -> 261613.71 | P17: =IF(B17<=55,$AL$5,$AN$6)*(IF(O17>=40000,40000,O17)) -> 2400 | Q17: =$AN$7*IF(O17>=40000,O17-40000,0) -> 11080.685 | R17: =O17+P17+Q17 -> 275094.39 | T17: =IF(B17<$BH$31,IF(B17<=35,$BH$4,IF(B18<=45,$BH$5,IF(B18<=50,$BH$6,IF(B18<=55,$BH$7,IF(B18<=60,$BH$8,IF(B18<=65,$BH$9,IF(B18<=70,$BH$10,$BH$11)))))))*'Retirement Dashboard'!$C$12,0) -> 2055.592 | U17: =IF(B17<($BH$57+$BH$30),$BH$56*12,0) -> 0 | V17: =IF(B17<=34,$AN$31,IF(B17<=39,$AN$32,IF(B17<=44,$AN$33,IF(B17<=49,$AN$34,IF(B17<=54,$AN$35,IF(B17<=59,$AN$36,IF(B17<=69,$AN$37,0))))))) -> 298 | W17: =Z16+T17-U17-V17 -> 108589.68 | X17: =IF(B17<=55,$AL$3,$AN$3)*(IF(W17>=20000,20000,W17)) -> 1200 | Y17: =$AL$4*IF(W17>=20000,W17-20000,W17) -> 2214.742 | Z17: =W17+X17+Y17 -> 112004.42 | AK17: <=50 | AL17: 525 | AM17: 600 | AR17: =AR16+1 -> 39 | AS17: =AS16+1 -> 2037 | AT17: =(AT16*103.5%) -> 160902.67 | AU17: =AU16*103.5% -> 321898.64 | AV17: =AV16*103.5% -> 643797.27 | AW17: =AW16+30 -> 1190 | AX17: =AX16+60 -> 2260 | AY17: =AY16*103.31% -> 4916.4539 | BA17: 42 | BB17: =(100%+$BB$3)*BB16 -> 320.86517 | BC17: =(100%+$BB$3)*BC16 -> 261.25781 | BD17: =(100%+$BD$3)*BD16 -> 839.57607
B18: =B17+1 -> 65 | C18: =IF(B18>=67,$BI$55,C17+(1.0244%*C17)) -> 446.54573 | D18: =IF(B18<=20,$AL$14,IF(B18<=30,$AL$15,IF(B18<=40,$AL$16,IF(B18<=50,$AL$17,IF(B18<=60,$AL$18,IF(B18<=65,$AL$19,IF(B18<=70,$AL$20, IF(B18<=73,$AL$21,IF(B18<=75,$AL$22,IF(B18<=78,$AL$23,IF(B18<=80,$AL$24,IF(B18<=83,$AL$25,IF(B18<=85,$AL$26,IF(B18<=90,$AL$27,$AL$28)))))))))))))) -> 1020 | E18: =IF(B18<=20,$AM$14,IF(B18<=30,$AM$15,IF(B18<=40,$AM$16,IF(B18<=50,$AM$17,IF(B18<=60,$AM$18,IF(B18<=65,$AM$19,IF(B18<=70,$AM$20, IF(B18<=73,$AM$21,IF(B18<=75,$AM$22,IF(B18<=78,$AM$23,IF(B18<=80,$AM$24,IF(B18<=83,$AM$25,IF(B18<=85,$AM$26,IF(B18<=90,$AM$27,$AM$28)))))))))))))) -> 600 | F18: =IF(AND('Retirement Dashboard'!$C$42="Yes", B18<= 'Retirement Dashboard'!$E$42), 600, 0) -> 600 | G18: =IF(B18<'Retirement Dashboard'!$E$6,IF(B18<=35,$BJ$4,IF(B18<=45,$BJ$5,IF(B18<=50,$BJ$6,IF(B18<=55,$BJ$7,IF(B18<=60,$BJ$8,IF(B18<=65,$BJ$9,IF(B18<=70,$BJ$10,$BJ$11)))))))*'Retirement Dashboard'!$C$12,0) -> 0 | H18: =K17-C18-D18-E18-F18+G18 -> 72833.454 | I18: =$AL$8*H18 -> 2913.3382 | J18: =IF(I18+H18-$AL$35>0,I18+H18-$AL$35,0) -> 246.79244 | K18: =H18+I18-J18 -> 75500 | M18: =IF(J18>=0,J18,0) -> 246.79244 | N18: =IF(B18<$BH$31,IF(B19<=35,$BI$4,IF(B19<=45,$BI$5,IF(B19<=50,$BI$6,IF(B19<=55,$BI$7,IF(B19<=60,$BI$8,IF(B19<=65,$BI$9,IF(B19<=70,$BI$10,$BI$11)))))))*'Retirement Dashboard'!$C$12,0) -> 0 | O18: =R17+N18+M18 -> 275341.19 | P18: =IF(B18<=55,$AL$5,$AN$6)*(IF(O18>=40000,40000,O18)) -> 2400 | Q18: =$AN$7*IF(O18>=40000,O18-40000,0) -> 11767.059 | R18: =O18+P18+Q18 -> 289508.25 | T18: =IF(B18<$BH$31,IF(B18<=35,$BH$4,IF(B19<=45,$BH$5,IF(B19<=50,$BH$6,IF(B19<=55,$BH$7,IF(B19<=60,$BH$8,IF(B19<=65,$BH$9,IF(B19<=70,$BH$10,$BH$11)))))))*'Retirement Dashboard'!$C$12,0) -> 0 | U18: =IF(B18<($BH$57+$BH$30),$BH$56*12,0) -> 0 | V18: =IF(B18<=34,$AN$31,IF(B18<=39,$AN$32,IF(B18<=44,$AN$33,IF(B18<=49,$AN$34,IF(B18<=54,$AN$35,IF(B18<=59,$AN$36,IF(B18<=69,$AN$37,0))))))) -> 298 | W18: =Z17+T18-U18-V18 -> 111706.42 | X18: =IF(B18<=55,$AL$3,$AN$3)*(IF(W18>=20000,20000,W18)) -> 1200 | Y18: =$AL$4*IF(W18>=20000,W18-20000,W18) -> 2292.6605 | Z18: =W18+X18+Y18 -> 115199.08 | AK18: <=60 | AL18: 800 | AM18: 600 | AR18: =AR17+1 -> 40 | AS18: =AS17+1 -> 2038 | AT18: =(AT17*103.5%) -> 166534.26 | AU18: =AU17*103.5% -> 333165.09 | AV18: =AV17*103.5% -> 666330.18 | AW18: =AW17+30 -> 1220 | AX18: =AX17+60 -> 2320 | AY18: =AY17*103.31% -> 5079.1885 | BA18: 43 | BB18: =(100%+$BB$3)*BB17 -> 327.28248 | BC18: =(100%+$BB$3)*BC17 -> 266.48297 | BD18: =(100%+$BD$3)*BD17 -> 856.36759
B19: =B18+1 -> 66 | C19: =IF(B19>=67,$BI$55,C18+(1.0244%*C18)) -> 451.12014 | D19: =IF(B19<=20,$AL$14,IF(B19<=30,$AL$15,IF(B19<=40,$AL$16,IF(B19<=50,$AL$17,IF(B19<=60,$AL$18,IF(B19<=65,$AL$19,IF(B19<=70,$AL$20, IF(B19<=73,$AL$21,IF(B19<=75,$AL$22,IF(B19<=78,$AL$23,IF(B19<=80,$AL$24,IF(B19<=83,$AL$25,IF(B19<=85,$AL$26,IF(B19<=90,$AL$27,$AL$28)))))))))))))) -> 1100 | E19: =IF(B19<=20,$AM$14,IF(B19<=30,$AM$15,IF(B19<=40,$AM$16,IF(B19<=50,$AM$17,IF(B19<=60,$AM$18,IF(B19<=65,$AM$19,IF(B19<=70,$AM$20, IF(B19<=73,$AM$21,IF(B19<=75,$AM$22,IF(B19<=78,$AM$23,IF(B19<=80,$AM$24,IF(B19<=83,$AM$25,IF(B19<=85,$AM$26,IF(B19<=90,$AM$27,$AM$28)))))))))))))) -> 600 | F19: =IF(AND('Retirement Dashboard'!$C$42="Yes", B19<= 'Retirement Dashboard'!$E$42), 600, 0) -> 600 | G19: =IF(B19<'Retirement Dashboard'!$E$6,IF(B19<=35,$BJ$4,IF(B19<=45,$BJ$5,IF(B19<=50,$BJ$6,IF(B19<=55,$BJ$7,IF(B19<=60,$BJ$8,IF(B19<=65,$BJ$9,IF(B19<=70,$BJ$10,$BJ$11)))))))*'Retirement Dashboard'!$C$12,0) -> 0 | H19: =K18-C19-D19-E19-F19+G19 -> 72748.88 | I19: =$AL$8*H19 -> 2909.9552 | J19: =IF(I19+H19-$AL$35>0,I19+H19-$AL$35,0) -> 158.83505 | K19: =H19+I19-J19 -> 75500 | M19: =IF(J19>=0,J19,0) -> 158.83505 | N19: =IF(B19<$BH$31,IF(B20<=35,$BI$4,IF(B20<=45,$BI$5,IF(B20<=50,$BI$6,IF(B20<=55,$BI$7,IF(B20<=60,$BI$8,IF(B20<=65,$BI$9,IF(B20<=70,$BI$10,$BI$11)))))))*'Retirement Dashboard'!$C$12,0) -> 0 | O19: =R18+N19+M19 -> 289667.08 | P19: =IF(B19<=55,$AL$5,$AN$6)*(IF(O19>=40000,40000,O19)) -> 2400 | Q19: =$AN$7*IF(O19>=40000,O19-40000,0) -> 12483.354 | R19: =O19+P19+Q19 -> 304550.44 | T19: =IF(B19<$BH$31,IF(B19<=35,$BH$4,IF(B20<=45,$BH$5,IF(B20<=50,$BH$6,IF(B20<=55,$BH$7,IF(B20<=60,$BH$8,IF(B20<=65,$BH$9,IF(B20<=70,$BH$10,$BH$11)))))))*'Retirement Dashboard'!$C$12,0) -> 0 | U19: =IF(B19<($BH$57+$BH$30),$BH$56*12,0) -> 0 | V19: =IF(B19<=34,$AN$31,IF(B19<=39,$AN$32,IF(B19<=44,$AN$33,IF(B19<=49,$AN$34,IF(B19<=54,$AN$35,IF(B19<=59,$AN$36,IF(B19<=69,$AN$37,0))))))) -> 298 | W19: =Z18+T19-U19-V19 -> 114901.08 | X19: =IF(B19<=55,$AL$3,$AN$3)*(IF(W19>=20000,20000,W19)) -> 1200 | Y19: =$AL$4*IF(W19>=20000,W19-20000,W19) -> 2372.527 | Z19: =W19+X19+Y19 -> 118473.61 | AK19: <=65 | AL19: 1020 | AM19: 600 | AR19: =AR18+1 -> 41 | AS19: =AS18+1 -> 2039 | AT19: =(AT18*103.5%) -> 172362.96 | AU19: =AU18*103.5% -> 344825.87 | AV19: =AV18*103.5% -> 689651.74 | AW19: =AW18+30 -> 1250 | AX19: =AX18+60 -> 2380 | AY19: =AY18*103.31% -> 5247.3096 | BA19: 44 | BB19: =(100%+$BB$3)*BB18 -> 333.82813 | BC19: =(100%+$BB$3)*BC18 -> 271.81263 | BD19: =(100%+$BD$3)*BD18 -> 873.49494
B20: =B19+1 -> 67 | C20: =IF(B20>=67,$BI$55,C19+(1.0244%*C19)) -> 0 | D20: =IF(B20<=20,$AL$14,IF(B20<=30,$AL$15,IF(B20<=40,$AL$16,IF(B20<=50,$AL$17,IF(B20<=60,$AL$18,IF(B20<=65,$AL$19,IF(B20<=70,$AL$20, IF(B20<=73,$AL$21,IF(B20<=75,$AL$22,IF(B20<=78,$AL$23,IF(B20<=80,$AL$24,IF(B20<=83,$AL$25,IF(B20<=85,$AL$26,IF(B20<=90,$AL$27,$AL$28)))))))))))))) -> 1100 | E20: =IF(B20<=20,$AM$14,IF(B20<=30,$AM$15,IF(B20<=40,$AM$16,IF(B20<=50,$AM$17,IF(B20<=60,$AM$18,IF(B20<=65,$AM$19,IF(B20<=70,$AM$20, IF(B20<=73,$AM$21,IF(B20<=75,$AM$22,IF(B20<=78,$AM$23,IF(B20<=80,$AM$24,IF(B20<=83,$AM$25,IF(B20<=85,$AM$26,IF(B20<=90,$AM$27,$AM$28)))))))))))))) -> 600 | F20: =IF(AND('Retirement Dashboard'!$C$42="Yes", B20<= 'Retirement Dashboard'!$E$42), 600, 0) -> 600 | G20: =IF(B20<'Retirement Dashboard'!$E$6,IF(B20<=35,$BJ$4,IF(B20<=45,$BJ$5,IF(B20<=50,$BJ$6,IF(B20<=55,$BJ$7,IF(B20<=60,$BJ$8,IF(B20<=65,$BJ$9,IF(B20<=70,$BJ$10,$BJ$11)))))))*'Retirement Dashboard'!$C$12,0) -> 0 | H20: =K19-C20-D20-E20-F20+G20 -> 73200 | I20: =$AL$8*H20 -> 2928 | J20: =IF(I20+H20-$AL$35>0,I20+H20-$AL$35,0) -> 628 | K20: =H20+I20-J20 -> 75500 | M20: =IF(J20>=0,J20,0) -> 628 | N20: =IF(B20<$BH$31,IF(B21<=35,$BI$4,IF(B21<=45,$BI$5,IF(B21<=50,$BI$6,IF(B21<=55,$BI$7,IF(B21<=60,$BI$8,IF(B21<=65,$BI$9,IF(B21<=70,$BI$10,$BI$11)))))))*'Retirement Dashboard'!$C$12,0) -> 0 | O20: =R19+N20+M20 -> 305178.44 | P20: =IF(B20<=55,$AL$5,$AN$6)*(IF(O20>=40000,40000,O20)) -> 2400 | Q20: =$AN$7*IF(O20>=40000,O20-40000,0) -> 13258.922 | R20: =O20+P20+Q20 -> 320837.36 | T20: =IF(B20<$BH$31,IF(B20<=35,$BH$4,IF(B21<=45,$BH$5,IF(B21<=50,$BH$6,IF(B21<=55,$BH$7,IF(B21<=60,$BH$8,IF(B21<=65,$BH$9,IF(B21<=70,$BH$10,$BH$11)))))))*'Retirement Dashboard'!$C$12,0) -> 0 | U20: =IF(B20<($BH$57+$BH$30),$BH$56*12,0) -> 0 | V20: =IF(B20<=34,$AN$31,IF(B20<=39,$AN$32,IF(B20<=44,$AN$33,IF(B20<=49,$AN$34,IF(B20<=54,$AN$35,IF(B20<=59,$AN$36,IF(B20<=69,$AN$37,0))))))) -> 298 | W20: =Z19+T20-U20-V20 -> 118175.61 | X20: =IF(B20<=55,$AL$3,$AN$3)*(IF(W20>=20000,20000,W20)) -> 1200 | Y20: =$AL$4*IF(W20>=20000,W20-20000,W20) -> 2454.3902 | Z20: =W20+X20+Y20 -> 121830 | AK20: <=70 | AL20: 1100 | AM20: 600 | AR20: =AR19+1 -> 42 | AS20: =AS19+1 -> 2040 | AT20: =(AT19*103.5%) -> 178395.66 | AU20: =AU19*103.5% -> 356894.77 | AV20: =AV19*103.5% -> 713789.55 | AW20: =AW19+30 -> 1280 | AX20: =AX19+60 -> 2440 | AY20: =AY19*103.31% -> 5420.9956 | BA20: 45 | BB20: =(100%+$BB$3)*BB19 -> 340.50469 | BC20: =(100%+$BB$3)*BC19 -> 277.24888 | BD20: =(100%+$BD$3)*BD19 -> 890.96484
